Workbook

Sheet 표지
B11: AI 기반 플랜트 통합관리 시스템 구축
B18: 과업내용서
D26: 2026. 04

Sheet 1. 요구사항 총괄표
B1: 요구사항 분류 | C1: 요구사항 고유번호 | D1: 요구사항 명칭
B2: 시스템 요구사항 | C2: ECR-001 | D2: =VLOOKUP(C2,'3. 요건기술서 전체'!$B:$L,5,0) -> 공통기능 -인프라 구성 표준
B3: 기능 요구사항 | C3: SFR-001 | D3: =VLOOKUP(C3,'3. 요건기술서 전체'!$B:$L,5,0) -> 공통기능 -계정 및 권한
B4: 기능 요구사항 | C4: SFR-002 | D4: =VLOOKUP(C4,'3. 요건기술서 전체'!$B:$L,5,0) -> 공통기능 -모바일
B5: 기능 요구사항 | C5: SFR-003 | D5: =VLOOKUP(C5,'3. 요건기술서 전체'!$B:$L,5,0) -> 공통기능 -정보 조회
B6: 기능 요구사항 | C6: SFR-004 | D6: =VLOOKUP(C6,'3. 요건기술서 전체'!$B:$L,5,0) -> 사용자 인터페이스(UI/UX)
B7: 기능 요구사항 | C7: SFR-005 | D7: =VLOOKUP(C7,'3. 요건기술서 전체'!$B:$L,5,0) -> 기능위치마스터 관리
B8: 기능 요구사항 | C8: SFR-006 | D8: =VLOOKUP(C8,'3. 요건기술서 전체'!$B:$L,5,0) -> 설비마스터 관리
B9: 기능 요구사항 | C9: SFR-007 | D9: =VLOOKUP(C9,'3. 요건기술서 전체'!$B:$L,5,0) -> 설비 BOM 관리
B10: 기능 요구사항 | C10: SFR-008 | D10: =VLOOKUP(C10,'3. 요건기술서 전체'!$B:$L,5,0) -> 스마트 도면 관리 기능(공통)
B11: 기능 요구사항 | C11: SFR-009 | D11: =VLOOKUP(C11,'3. 요건기술서 전체'!$B:$L,5,0) -> 스마트 도면 전환
B12: 기능 요구사항 | C12: SFR-010 | D12: =VLOOKUP(C12,'3. 요건기술서 전체'!$B:$L,5,0) -> 스마트 도면 편집(Edit) 기능
B13: 기능 요구사항 | C13: SFR-011 | D13: =VLOOKUP(C13,'3. 요건기술서 전체'!$B:$L,5,0) -> 스마트 도면 보기(View) 기능
... B73: 기능 요구사항 | C73: SFR-071 | D73: =VLOOKUP(C73,'3. 요건기술서 전체'!$B:$L,5,0) -> 공통기능 - 매뉴얼관리
B74: 기능 요구사항 | C74: SFR-072 | D74: 시스템 성과측정 및 로그 개발
B75: 보안 요구사항 | C75: SER-001 | D75: =VLOOKUP(C75,'3. 요건기술서 전체'!$B:$L,5,0) -> 공통기능 -외부 접근 제한
B76: 보안 요구사항 | C76: SER-002 | D76: =VLOOKUP(C76,'3. 요건기술서 전체'!$B:$L,5,0) -> 정보누출금지
B77: 보안 요구사항 | C77: SER-003 | D77: =VLOOKUP(C77,'3. 요건기술서 전체'!$B:$L,5,0) -> 보안위규 처리 기준
B78: 보안 요구사항 | C78: SER-004 | D78: =VLOOKUP(C78,'3. 요건기술서 전체'!$B:$L,5,0) -> 보안위약금 부과 기준
B79: 보안 요구사항 | C79: SER-005 | D79: =VLOOKUP(C79,'3. 요건기술서 전체'!$B:$L,5,0) -> 보안 사항
B80: 보안 요구사항 | C80: SER-006 | D80: =VLOOKUP(C80,'3. 요건기술서 전체'!$B:$L,5,0) -> 망 접근 관련 보안사항
B81: 보안 요구사항 | C81: SER-007 | D81: 사업 진행 단계별 보안 사항
B82: 보안 요구사항 | C82: SER-008 | D82: 로그인, 사용자 정보 관리
B83: 보안 요구사항 | C83: SER-009 | D83: 시큐어 코딩 및 보안 취약점 제거
B84: 보안 요구사항 | C84: SER-010 | D84: 데이터 및 DB 암호화
B85: 보안 요구사항 | C85: SER-011 | D85: 개인정보보호법 관련 준수
B86: 보안 요구사항 | C86: SER-012 | D86: 기타 보안사항
B87: 보안 요구사항 | C87: SER-013 | D87: API 보안 관리
B88: 데이터 요구사항 | C88: DAR-001 | D88: =VLOOKUP(C88,'3. 요건기술서 전체'!$B:$L,5,0) -> 데이터 표준 수립 및 상위표준 준수
B89: 데이터 요구사항 | C89: DAR-002 | D89: =VLOOKUP(C89,'3. 요건기술서 전체'!$B:$L,5,0) -> 데이터 표준관리
B90: 데이터 요구사항 | C90: DAR-003 | D90: =VLOOKUP(C90,'3. 요건기술서 전체'!$B:$L,5,0) -> 데이터 구조 설계
B91: 데이터 요구사항 | C91: DAR-004 | D91: =VLOOKUP(C91,'3. 요건기술서 전체'!$B:$L,5,0) -> 데이터 구조 검증
B92: 데이터 요구사항 | C92: DAR-005 | D92: =VLOOKUP(C92,'3. 요건기술서 전체'!$B:$L,5,0) -> 데이터 구조 관리
B93: 데이터 요구사항 | C93: DAR-006 | D93: =VLOOKUP(C93,'3. 요건기술서 전체'!$B:$L,5,0) -> 데이터 값 검증
B94: 데이터 요구사항 | C94: DAR-007 | D94: =VLOOKUP(C94,'3. 요건기술서 전체'!$B:$L,5,0) -> 이관 데이터 값 검증
B95: 데이터 요구사항 | C95: DAR-008 | D95: =VLOOKUP(C95,'3. 요건기술서 전체'!$B:$L,5,0) -> 데이터 관리체계 수립
B96: 데이터 요구사항 | C96: DAR-009 | D96: =VLOOKUP(C96,'3. 요건기술서 전체'!$B:$L,5,0) -> 데이터 개방 및 메타데이터 관리체계
B97: 데이터 요구사항 | C97: DAR-010 | D97: =VLOOKUP(C97,'3. 요건기술서 전체'!$B:$L,5,0) -> DB 관리 방안
B98: 데이터 요구사항 | C98: DAR-011 | D98: =VLOOKUP(C98,'3. 요건기술서 전체'!$B:$L,5,0) -> DB 표준 준수
B99: 데이터 요구사항 | C99: DAR-012 | D99: =VLOOKUP(C99,'3. 요건기술서 전체'!$B:$L,5,0) -> AI 지원을 위한 데이터 구조 표준 수립
...

Sheet 2. 요구사항 정의서
B2: 요구사항 분류 | D2: ='1. 요구사항 총괄표'!B2 -> 시스템 요구사항 | E2: 응락수준 | F2: =VLOOKUP($D3,'3. 요건기술서 전체'!$B:$L,6,0) -> 필수 | H2: 시스템 요구사항
B3: 요구사항 고유번호 | D3: ='1. 요구사항 총괄표'!C2 -> ECR-001 | E3: 모바일 | F3: =IFERROR(TRIM(IF(VLOOKUP($D3,'3. 요건기술서 전체'!$B:$L,10,0)<>"",IF(VLOOKUP($D3,'3. 요건기술서 전체'!$B:$L,10,0)="O", "한난O", IF(VLOOKUP($D3,'3. 요건기술서 전체'!$B:$L,10,0)="X", "한난X", "")),"") & " " &IF(VLOOKUP($D3,'3. 요건기술서 전체'!$B:$L,11,0)<>"",IF(VLOOKUP($D3,'3. 요건기술서 전체'!$B:$L,11,0)="O", "외부O", IF(VLOOKUP($D3,'3. 요건기술서 전체'!$B:$L,11,0)="X", "외부X", "")),"")),"") | H3: ECR-001
B4: 요구사항 명칭 | D4: =VLOOKUP($D3,'3. 요건기술서 전체'!$B:$L,5,0) -> 공통기능 -인프라 구성 표준 | H4: 공통기능 -인프라 구성 표준
B5: 요구사항 상세설명 | C5: 정의 | D5: =VLOOKUP($D3,'3. 요건기술서 전체'!$B:$L,7,0) -> 인프라 구성 표준 | H5: 인프라 구성 표준
C6: 세부내용 | D6: =VLOOKUP($D3,'3. 요건기술서 전체'!$B:$L,8,0) -> ○ IT 인프라 구성 표준 - OS : RHEL 9.4 이상 - JDK : OpenJDK 17 이상 - WEB : nginx 1.28 이상 - WAS : Tomcat 9 이상 - DB : Oracle 19c (Standard) ○ 개발환경 구성 표준 - 전자정부프레임워크 기반 개발환경 준수 ○ IT 인프라 구성 표준 준수 시, 우리 공사의 가상서버 제공 및 운영 지원 ○ IT 인프라 구성 표준 및 개발환경 구성 표준 미준수 시, 제안사 직접 납품 및 운영·유지보수 방안 제시 필수 ○ WEB/WAS/DB 등의 운영 Port는 우리 공사가 지정한 Port로 변경 운영 필수(Well -Known Port 사용 불가) ○ 우리 공사 직원의 업무환경인 가상 데스크탑 환경(VDI. 이하, 내부 업무환경)에서 속도 저하 및 지연없이 모든 서비스 제공 ○ Microsoft Edge 브라우저에서 추가 프로그램(플러그인 등) 설치없이 모든 기능 제공 | H6: ○ IT 인프라 구성 표준 - OS : RHEL 9.4 이상 - JDK : OpenJDK 17 이상 - WEB : nginx 1.28 이상 - WAS : Tomcat 9 이상 - DB : Oracle 19c (Standard) ○ 개발환경 구성 표준 - 전자정부프레임워크 기반 개발환경 준수 ○ IT 인프라 구성 표준 준수 시, 우리 공사의 가상서버 제공 및 운영 지원 ○ IT 인프라 구성 표준 및 개발환경 구성 표준 미준수 시, 제안사 직접 납품 및 운영·유지보수 방안 제시 필수 ○ WEB/WAS/DB 등의 운영 Port는 우리 공사가 지정한 Port로 변경 운영 필수(Well -Known Port 사용 불가) ○ 우리 공사 직원의 업무환경인 가상 데스크탑 환경(VDI. 이하, 내부 업무환경)에서 속도 저하 및 지연없이 모든 서비스 제공 ○ Microsoft Edge 브라우저에서 추가 프로그램(플러그인 등) 설치없이 모든 기능 제공
B7: 산출정보 | D7: =VLOOKUP(D3, '3. 요건기술서 전체'!$B:$L, 9, 0) -> 아키텍쳐 설계서 | H7: 아키텍쳐 설계서
B8: 관련 요구사항 | D8: =VLOOKUP($D3,'3. 요건기술서 전체'!$B:$L,2,0) -> 0 | H8: 0
B10: 요구사항 분류 | D10: 기능 요구사항 | E10: 응락수준 | F10: =VLOOKUP($D11,'3. 요건기술서 전체'!$B:$L,6,0) -> 필수 | H10: 기능 요구사항
B11: 요구사항 고유번호 | D11: ='1. 요구사항 총괄표'!C3 -> SFR-001 | E11: 모바일 | F11: =IFERROR(TRIM(IF(VLOOKUP($D11,'3. 요건기술서 전체'!$B:$L,10,0)<>"",IF(VLOOKUP($D11,'3. 요건기술서 전체'!$B:$L,10,0)="O", "한난O", IF(VLOOKUP($D11,'3. 요건기술서 전체'!$B:$L,10,0)="X", "한난X", "")),"") & " " &IF(VLOOKUP($D11,'3. 요건기술서 전체'!$B:$L,11,0)<>"",IF(VLOOKUP($D11,'3. 요건기술서 전체'!$B:$L,11,0)="O", "외부O", IF(VLOOKUP($D11,'3. 요건기술서 전체'!$B:$L,11,0)="X", "외부X", "")),"")),"") | H11: SFR-001
B12: 요구사항 명칭 | D12: =VLOOKUP($D11,'3. 요건기술서 전체'!$B:$L,5,0) -> 공통기능 -계정 및 권한 | H12: 공통기능 -계정 및 권한
B13: 요구사항 상세설명 | C13: 정의 | D13: =VLOOKUP($D11,'3. 요건기술서 전체'!$B:$L,7,0) -> 계정 및 권한 | H13: 계정 및 권한
C14: 세부내용 | D14: =VLOOKUP($D11,'3. 요건기술서 전체'!$B:$L,8,0) -> ○ 계정 및 권한관리 - 로그인 계정별 관리자 권한과 사용자 권한 관리 기능 - 관리자 권한으로 권한 그룹 관리 및 주요 시스템 설정 수행 - 사용자별 권한 및 역할에 따른 관리 기능(메뉴접근/승인/조회/공사/작업/예약/주요정보 등) - 외부 협력사 계정은 계약 기간에 따른 '사용 유효기간(Expiry Date)' 설정 기능을 필수 제공하고, 기간 만료 시 자동 잠금(Lock) 처리되어야 함 - 계약 만료일 이전에 사전 만료일 통보 및 자동 연장 기능 제공 ○ 로그인 시 보직 선택 기능 제공 - 인사 시스템의 '부서' 정보만으로는 사용자의 구체적인 수행 업무(기계/전기/제어/안전 등)를 식별할 수 없으므로, 최초 로그인 또는 권한 변경 필요 시 사용자가 자신의 '보직(Role)'을 직접 선택할 수 있는 팝업 화면을 제공해야 한다. ○ 보직 선택에 따른 권한 자동 매핑 - 사용자가 선택한 보직에 따라, 사전에 정의된 '권한 그룹(Role)'과 '메뉴 접근 권한'이 즉시 시스템에 반영되어야 한다. ○ 다중 보직 및 겸직 지원 - 2개 이상의 보직을 수행하는 겸직 사용자(파견 등) 를 위해, 로그인 후에도 상단 메뉴바 등을 통해 보직(Workspace) 전환이 가능하도록 구현해야 한다. ○ 보직 변경 이력 관리 - 사용자가 보직을 선택하거나 변경한 이력(변경일시, 변경 전/후 보직, 접속 IP 등)은 시스템에 기록 및 보관되어야 한다. ○ 동일 ID 중복 역할인 경우, 한 번에 처리 - 두 가지 이상 직책을 동일 직원이 중복해서 맡을 경우, 중복업무를 한 번에 처리(동일 ID로 검토 시 동일 문건 중 한 건이 처리되면 다른 건도 자동으로 처리) EX) (당초) 홍길동 기안 – 홍길동 팀장 – OOO 부장 -> (변경) 홍길동 기안 – (생략) – OOO 부장 ○ Project OBS 설정 방법 - 인사발령 등으로 인한 변경시 즉시 반영될 수 있도록 OBS(Organization Breakdown Structure) 설정 방법에 대한 개선 - 관리자가 변경되는 조직에 맞게 OBS를 유동적으로 변경할 수 있도록 설정 가능 | H14: ○ 계정 및 권한관리 - 로그인 계정별 관리자 권한과 사용자 권한 관리 기능 - 관리자 권한으로 권한 그룹 관리 및 주요 시스템 설정 수행 - 사용자별 권한 및 역할에 따른 관리 기능(메뉴접근/승인/조회/공사/작업/예약/주요정보 등) - 외부 협력사 계정은 계약 기간에 따른 '사용 유효기간(Expiry Date)' 설정 기능을 필수 제공하고, 기간 만료 시 자동 잠금(Lock) 처리되어야 함 ○ 로그인 시 보직 선택 기능 제공 - 인사 시스템의 '부서' 정보만으로는 사용자의 구체적인 수행 업무(기계/전기/제어/안전 등)를 식별할 수 없으므로, 최초 로그인 또는 권한 변경 필요 시 사용자가 자신의 '보직(Role)'을 직접 선택할 수 있는 팝업 화면을 제공해야 한다. ○ 보직 선택에 따른 권한 자동 매핑 - 사용자가 선택한 보직에 따라, 사전에 정의된 '권한 그룹(Role)'과 '메뉴 접근 권한'이 즉시 시스템에 반영되어야 한다. ○ 다중 보직 및 겸직 지원 - 2개 이상의 보직을 수행하는 겸직 사용자(파견 등) 를 위해, 로그인 후에도 상단 메뉴바 등을 통해 보직(Workspace) 전환이 가능하도록 구현해야 한다. ○ 보직 변경 이력 관리 - 사용자가 보직을 선택하거나 변경한 이력(변경일시, 변경 전/후 보직, 접속 IP 등)은 시스템에 기록 및 보관되어야 한다. ○ 동일 ID 중복 역할인 경우, 한 번에 처리 - 두 가지 이상 직책을 동일 직원이 중복해서 맡을 경우, 중복업무를 한 번에 처리(동일 ID로 검토 시 동일 문건 중 한 건이 처리되면 다른 건도 자동으로 처리) EX) (당초) 홍길동 기안 – 홍길동 팀장 – OOO 부장 -> (변경) 홍길동 기안 – (생략) – OOO 부장 ○ Project OBS 설정 방법 - 인사발령 등으로 인한 변경시 즉시 반영될 수 있도록 OBS(Organization Breakdown Structure) 설정 방법에 대한 개선 - 관리자가 변경되는 조직에 맞게 OBS를 유동적으로 변경할 수 있도록 설정 가능
B15: 산출정보 | D15: =VLOOKUP(D11, '3. 요건기술서 전체'!$B:$L, 9, 0) -> 메뉴구성 및 권한정의서 | H15: 메뉴구성 및 권한정의서
B16: 관련 요구사항 | D16: =VLOOKUP($D11,'3. 요건기술서 전체'!$B:$L,2,0) -> 0 | H16: 0
B18: 요구사항 분류 | D18: 기능 요구사항 | E18: 응락수준 | F18: =VLOOKUP($D19,'3. 요건기술서 전체'!$B:$L,6,0) -> 필수 | H18: 기능 요구사항
B19: 요구사항 고유번호 | D19: =LEFT(D11,3)&"-"&TEXT(VALUE(RIGHT(D11,3))+1,"000") -> SFR-002 | E19: 모바일 | F19: =IFERROR(TRIM(IF(VLOOKUP($D19,'3. 요건기술서 전체'!$B:$L,10,0)<>"",IF(VLOOKUP($D19,'3. 요건기술서 전체'!$B:$L,10,0)="O", "한난O", IF(VLOOKUP($D19,'3. 요건기술서 전체'!$B:$L,10,0)="X", "한난X", "")),"") & " " &IF(VLOOKUP($D19,'3. 요건기술서 전체'!$B:$L,11,0)<>"",IF(VLOOKUP($D19,'3. 요건기술서 전체'!$B:$L,11,0)="O", "외부O", IF(VLOOKUP($D19,'3. 요건기술서 전체'!$B:$L,11,0)="X", "외부X", "")),"")),"") | H19: SFR-002
B20: 요구사항 명칭 | D20: =VLOOKUP($D19,'3. 요건기술서 전체'!$B:$L,5,0) -> 공통기능 -모바일 | H20: 공통기능 -모바일
B21: 요구사항 상세설명 | C21: 정의 | D21: =VLOOKUP($D19,'3. 요건기술서 전체'!$B:$L,7,0) -> 모바일 공통 기능 | H21: 모바일 공통 기능
C22: 세부내용 | D22: =VLOOKUP($D19,'3. 요건기술서 전체'!$B:$L,8,0) -> ○ 모바일 공통 기능 - 기능 요구사항에서 '모바일'로 표시된 기능은 내부 직원 및 외부(협력사/시공사 등) 직원으로 구분하여 모바일에서 제공 - 모바일은 Android OS 와 iOS 를 지원 - 사용자별 권한 및 역할에 따른 승인 처리 기능 - 승인/이상/공사/작업/예약/주요정보 등의 알림(알람)을 모바일 PUSH로 제공 ○ 모바일 기능은 개인 모바일, 지급형 단말기(내부망 접근) 구성으로 분리하여 제공 - 시스템은 사용자가 접속한 단말기 유형(개인용/지급형)과 네트워크(외부망/내부망)을 자동식별하여, 그에 맞는 메인화면과 메뉴트리를 동적으로 구성 ○ 모바일 기능은 우리 공사에서 기 운영 중인 '스마트 안전관리' 모바일 앱과 분리하여 별도로 운영할 수 있는 방안 제안 필수 ○ 모바일 기능은 우리 공사의 보안등급(C -Classified, 기밀/S -Sensitive, 민감/O -Open, 공개)을 준용하여 보안성 검토를 받아야 한다 ○ 모바일 기능은 모바일 환경(개인모바일, 지급형 단말기) UI/UX 최적화 ○ 네트워크 음영지역(지하 공동구 등)에서도 점검 결과 입력 및 조회가 가능하도록 오프라인 모드(Data Caching & Sync) 기능 필수 제공 ○ 모바일 보안을 위해 화면 캡처 방지, 루팅 감지 등 공사 모바일 보안 가이드라인 준수 및 MDM 연동 지원 ○ 하이브리드/웹 표준 기반 디바이스 제어: 모바일 웹 환경에서도 현장 업무 처리를 위해 스마트폰의 카메라, GPS, 파일 시스템에 직접 접근할 수 있는 Web API 또는 하이브리드 브릿지 기술을 적용해야 한다. ○ QR/바코드 스캔 및 처리: 별도의 스캐너 장비 없이 스마트폰 카메라를 통해 자재/설비의 QR(바코드)를 인식하고, 즉시 해당 정보 조회 화면으로 이동하거나 데이터를 입력하는 기능을 제공해야 한다. ○ 현장 사진 촬영 및 최적화: 현장에서 점검/보수 내역 작성 시 카메라를 호출하여 사진을 촬영하고, 서버 전송 용량 최적화(리사이징/압축) 후 즉시 첨부하는 기능을 제공해야 한다. ○ 위치 기반(GPS) 작업 통제: 작업자가 실제 현장에 도착했는지 확인하기 위해 GPS 좌표를 수집한다.(GPS 수집 대상 단말기와 대상은 구축시 협의) | H22: ○ 모바일 공통 기능 - 기능 요구사항에서 '모바일'로 표시된 기능은 내부 직원 및 외부(협력사/시공사 등) 직원으로 구분하여 모바일에서 제공 - 모바일은 Android OS 와 iOS 를 지원 - 사용자별 권한 및 역할에 따른 승인 처리 기능 - 승인/이상/공사/작업/예약/주요정보 등의 알림(알람)을 모바일 PUSH로 제공 ○ 모바일 기능은 개인 모바일, 지급형 단말기(내부망 접근) 구성으로 분리하여 제공 - 시스템은 사용자가 접속한 단말기 유형(개인용/지급형)과 네트워크(외부망/내부망)을 자동식별하여, 그에 맞는 메인화면과 메뉴트리를 동적으로 구성 ○ 모바일 기능은 우리 공사에서 기 운영 중인 '스마트 안전관리' 모바일 앱과 분리하여 별도로 운영할 수 있는 방안 제안 필수 ○ 모바일 기능은 우리 공사의 보안등급(C -Classified, 기밀/S -Sensitive, 민감/O -Open, 공개)을 준용하여 보안성 검토를 받아야 한다 ○ 모바일 기능은 모바일 환경(개인모바일, 지급형 단말기) UI/UX 최적화 ○ 네트워크 음영지역(지하 공동구 등)에서도 점검 결과 입력 및 조회가 가능하도록 오프라인 모드(Data Caching & Sync) 기능 필수 제공 ○ 모바일 보안을 위해 화면 캡처 방지, 루팅 감지 등 공사 모바일 보안 가이드라인 준수 및 MDM 연동 지원 ○ 하이브리드/웹 표준 기반 디바이스 제어: 모바일 웹 환경에서도 현장 업무 처리를 위해 스마트폰의 카메라, GPS, 파일 시스템에 직접 접근할 수 있는 Web API 또는 하이브리드 브릿지 기술을 적용해야 한다. ○ QR/바코드 스캔 및 처리: 별도의 스캐너 장비 없이 스마트폰 카메라를 통해 자재/설비의 QR(바코드)를 인식하고, 즉시 해당 정보 조회 화면으로 이동하거나 데이터를 입력하는 기능을 제공해야 한다. ○ 현장 사진 촬영 및 최적화: 현장에서 점검/보수 내역 작성 시 카메라를 호출하여 사진을 촬영하고, 서버 전송 용량 최적화(리사이징/압축) 후 즉시 첨부하는 기능을 제공해야 한다. ○ 위치 기반(GPS) 작업 통제: 작업자가 실제 현장에 도착했는지 확인하기 위해 GPS 좌표를 수집한다.(GPS 수집 대상 단말기와 대상은 구축시 협의)
B23: 산출정보 | D23: =VLOOKUP(D19, '3. 요건기술서 전체'!$B:$L, 9, 0) -> 0 | H23: 0
B24: 관련 요구사항 | D24: =VLOOKUP($D19,'3. 요건기술서 전체'!$B:$L,2,0) -> 0 | H24: 0
B26: 요구사항 분류 | D26: 기능 요구사항 | E26: 응락수준 | F26: =VLOOKUP($D27,'3. 요건기술서 전체'!$B:$L,6,0) -> 필수 | H26: 기능 요구사항
B27: 요구사항 고유번호 | D27: =LEFT(D19,3)&"-"&TEXT(VALUE(RIGHT(D19,3))+1,"000") -> SFR-003 | E27: 모바일 | F27: =IFERROR(TRIM(IF(VLOOKUP($D27,'3. 요건기술서 전체'!$B:$L,10,0)<>"",IF(VLOOKUP($D27,'3. 요건기술서 전체'!$B:$L,10,0)="O", "한난O", IF(VLOOKUP($D27,'3. 요건기술서 전체'!$B:$L,10,0)="X", "한난X", "")),"") & " " &IF(VLOOKUP($D27,'3. 요건기술서 전체'!$B:$L,11,0)<>"",IF(VLOOKUP($D27,'3. 요건기술서 전체'!$B:$L,11,0)="O", "외부O", IF(VLOOKUP($D27,'3. 요건기술서 전체'!$B:$L,11,0)="X", "외부X", "")),"")),"") | H27: SFR-003
B28: 요구사항 명칭 | D28: =VLOOKUP($D27,'3. 요건기술서 전체'!$B:$L,5,0) -> 공통기능 -정보 조회 | H28: 공통기능 -정보 조회
B29: 요구사항 상세설명 | C29: 정의 | D29: =VLOOKUP($D27,'3. 요건기술서 전체'!$B:$L,7,0) -> 정보 조회 기능 | H29: 정보 조회 기능
C30: 세부내용 | D30: =VLOOKUP($D27,'3. 요건기술서 전체'!$B:$L,8,0) -> ○ 정보 조회 기능 - 로그인한 사용자의 소속 지사를 기준으로 자재·설비·작업·공사 등의 정보 조회 - 모든 정보는 사용자의 조회 조건에 따라 소속 지사 정보와 타지사 정보 조회 가능 - 조회 결과로 표시되는 모든 항목에 대해 조회 조건을 설정할 수 있어야 하며, 문자열·숫자·날짜·부울값 등의 범위·값·포함여부조건 등 설정 기능 - 모든 항목에 대한 조건 검색 시, 대용량 데이터 조회 속도 보장을 위한 서버 사이드(Server-side) 필터링 및 인덱싱 최적화 방안 제시 - 협력사 사용자의 메뉴 접근 및 메뉴별 정보 조회·등록·수정 등 권한 설정 기능 - PDF/이미지 파일 등은 다운로드 및 브라우저에서 직접 보기 기능 직접보기 기능 구현을 위한 상용 뷰어 솔루션은 직접구매 제공 예정이며, 시스템과 연계 및 최적화 지원 - 모든 조회 결과는 엑셀 다운로드 기능 제공(모바일 환경 시, 다운로드 기능 제외) - 승인이 필요한 업무의 경우, 승인선관리/진행단계표시/승인/반려 등의 정보 조회 기능(시스템 內 승인 처리 기능) - 우리 공사 전자결재를 활용한 승인 업무의 경우, 전자결재 연계 처리 및 진행상태 조회 기능 - 업무별 우리 공사 보고서 양식을 준수하는 출력 기능 제공 ○ 모바일 기능은 개인 모바일, 지급형 단말기(내부망 접근) 접근에 따라 정보 조회 및 권한 차등 적용 - 개인용 : 보안과 무관한 일반업무 위주의 경량화된 UI 제공(현장점검 입력, 로그시트입력, TM발행, 현장사진 업로드 기능 등) - 지급형 : 현장점검, 설비 및 도면 조회 등 핵심업무 수행을 위한 데이터 중심 UI 제공(VPN 및 공사 보안 규정 및 국정원 가이드라인 준수) ○ 통계 기능 - 주요 기능 및 업무에 대한 통계 정보 제공(통계 대상 및 범위는 사업 수행 시, 협의) - 관리자 또는 사용자의 통계 정보 범위, 대상, 결과, 차트 등의 변경/설정 기능 제공 | H30: ○ 정보 조회 기능 - 로그인한 사용자의 소속 지사를 기준으로 자재·설비·작업·공사 등의 정보 조회 - 모든 정보는 사용자의 조회 조건에 따라 소속 지사 정보와 타지사 정보 조회 가능 - 조회 결과로 표시되는 모든 항목에 대해 조회 조건을 설정할 수 있어야 하며, 문자열·숫자·날짜·부울값 등의 범위·값·포함여부조건 등 설정 기능 - 모든 항목에 대한 조건 검색 시, 대용량 데이터 조회 속도 보장을 위한 서버 사이드(Server-side) 필터링 및 인덱싱 최적화 방안 제시 - 협력사 사용자의 메뉴 접근 및 메뉴별 정보 조회·등록·수정 등 권한 설정 기능 - PDF/이미지 파일 등은 다운로드 및 브라우저에서 직접 보기 기능 직접보기 기능 구현을 위한 상용 뷰어 솔루션은 직접구매 제공 예정이며, 시스템과 연계 및 최적화 지원 - 모든 조회 결과는 엑셀 다운로드 기능 제공(모바일 환경 시, 다운로드 기능 제외) - 승인이 필요한 업무의 경우, 승인선관리/진행단계표시/승인/반려 등의 정보 조회 기능(시스템 內 승인 처리 기능) - 우리 공사 전자결재를 활용한 승인 업무의 경우, 전자결재 연계 처리 및 진행상태 조회 기능 - 업무별 우리 공사 보고서 양식을 준수하는 출력 기능 제공 ○ 모바일 기능은 개인 모바일, 지급형 단말기(내부망 접근) 접근에 따라 정보 조회 및 권한 차등 적용 - 개인용 : 보안과 무관한 일반업무 위주의 경량화된 UI 제공(현장점검 입력, 로그시트입력, TM발행, 현장사진 업로드 기능 등) - 지급형 : 현장점검, 설비 및 도면 조회 등 핵심업무 수행을 위한 데이터 중심 UI 제공(VPN 및 공사 보안 규정 및 국정원 가이드라인 준수) ○ 통계 기능 - 주요 기능 및 업무에 대한 통계 정보 제공(통계 대상 및 범위는 사업 수행 시, 협의) - 관리자 또는 사용자의 통계 정보 범위, 대상, 결과, 차트 등의 변경/설정 기능 제공
B31: 산출정보 | D31: =VLOOKUP(D27, '3. 요건기술서 전체'!$B:$L, 9, 0) -> 0 | H31: 0
B32: 관련 요구사항 | D32: =VLOOKUP($D27,'3. 요건기술서 전체'!$B:$L,2,0) -> 0 | H32: 0
B34: 요구사항 분류 | D34: 기능 요구사항 | E34: 응락수준 | F34: =VLOOKUP($D35,'3. 요건기술서 전체'!$B:$L,6,0) -> 필수 | H34: 기능 요구사항
B35: 요구사항 고유번호 | D35: =LEFT(D27,3)&"-"&TEXT(VALUE(RIGHT(D27,3))+1,"000") -> SFR-004 | E35: 모바일 | F35: =IFERROR(TRIM(IF(VLOOKUP($D35,'3. 요건기술서 전체'!$B:$L,10,0)<>"",IF(VLOOKUP($D35,'3. 요건기술서 전체'!$B:$L,10,0)="O", "한난O", IF(VLOOKUP($D35,'3. 요건기술서 전체'!$B:$L,10,0)="X", "한난X", "")),"") & " " &IF(VLOOKUP($D35,'3. 요건기술서 전체'!$B:$L,11,0)<>"",IF(VLOOKUP($D35,'3. 요건기술서 전체'!$B:$L,11,0)="O", "외부O", IF(VLOOKUP($D35,'3. 요건기술서 전체'!$B:$L,11,0)="X", "외부X", "")),"")),"") | H35: SFR-004
B36: 요구사항 명칭 | D36: =VLOOKUP($D35,'3. 요건기술서 전체'!$B:$L,5,0) -> 사용자 인터페이스(UI/UX) | H36: 사용자 인터페이스(UI/UX)
B37: 요구사항 상세설명 | C37: 정의 | D37: =VLOOKUP($D35,'3. 요건기술서 전체'!$B:$L,7,0) -> 사용자 인터페이스(UI/UX) | H37: 사용자 인터페이스(UI/UX)
C38: 세부내용 | D38: =VLOOKUP($D35,'3. 요건기술서 전체'!$B:$L,8,0) -> ○ 사용자 인터페이스 - 목록 정보는 그리드 형태로 표시하며, 각 열의 그리드 헤더에서 조회 조건(문자열·숫자·날짜·부울값 등) 범위·값·포함여부조건 등 설정 기능 - 조회 결과는 일정량을 우선 표시하고, 스크롤 시 조회 결과 추가(Fetch) 또는 기능 - 조회 결과에서 특정 열 선택 시, 새창/새탭/팝업 등으로 상세 정보 및 연관 정보 표시 기능 - 탭의 경우, 새탭 생성 시 최초 로딩 이후 탭 간 이동 시 로딩 제거(탭별 사용자 새로고침에 의한 로딩) - 탭 방식 인터페이스 구현 시, 다중 탭 오픈에 따른 클라이언트(VDI 환경 포함) 메모리 점유율 최적화 방안(비활성 탭 리소스 관리 등) 제시 - 사용자 즐겨찾기 메뉴 구성 기능 - 사이드 메뉴/상단 메뉴 등 화면을 구성하는 주요 콤포넌트의 보이기/숨기기 기능 - 주요 알림 및 긴급 알람 등은 모든 메뉴의 공통 영역에서 실시간 표시(숫자/리스트/요약정보/상세정보 등)하고 상시 관련 정보 접근 가능 - 주요 입력 항목의 설명 및 도움말 제공(툴팁 등), 필수값 입력 강제 등의 검증 기능 - 사용자 편의성을 보장하는 UI/UX 제공 - 사용자 중심의 UI/UX 설계 - 사용자는 End to End 로 업무프로세스가 진행되는것 을 확인할 수 있도록 상단에 현재 업무과정을 표기하여야한다. - 상단의 업무프로세스 UI를 클릭스 타 레거시의 해당 메뉴로 진입할 수 있도록 URL을 연결한다. - 상단의 업무프로세스 과정에서 타부서의 결재 과정이나, 시스템의 오류사항을 수시로 점검하여 반영한다. ○ 외부망 웹페이지는 협력사의 다양한 PC환경 및 모바일 브라우저를 고려하여 반응형(또는 모바일웹) 등 최적화된 UI/UX를 제공 ○ 전사 UI/UX 표준화를 위한 웹 디자인을 제시하여 업무시스템간 시각적,기능적 통일성을 확보하고 유사한 사용자 경험을 제공 (HTML5 기반 업무포털과 연계하여 포털 중앙화면에서 통합 제공 등) | H38: ○ 사용자 인터페이스 - 목록 정보는 그리드 형태로 표시하며, 각 열의 그리드 헤더에서 조회 조건(문자열·숫자·날짜·부울값 등) 범위·값·포함여부조건 등 설정 기능 - 조회 결과는 일정량을 우선 표시하고, 스크롤 시 조회 결과 추가(Fetch) 또는 기능 - 조회 결과에서 특정 열 선택 시, 새창/새탭/팝업 등으로 상세 정보 및 연관 정보 표시 기능 - 탭의 경우, 새탭 생성 시 최초 로딩 이후 탭 간 이동 시 로딩 제거(탭별 사용자 새로고침에 의한 로딩) - 탭 방식 인터페이스 구현 시, 다중 탭 오픈에 따른 클라이언트(VDI 환경 포함) 메모리 점유율 최적화 방안(비활성 탭 리소스 관리 등) 제시 - 사용자 즐겨찾기 메뉴 구성 기능 - 사이드 메뉴/상단 메뉴 등 화면을 구성하는 주요 콤포넌트의 보이기/숨기기 기능 - 주요 알림 및 긴급 알람 등은 모든 메뉴의 공통 영역에서 실시간 표시(숫자/리스트/요약정보/상세정보 등)하고 상시 관련 정보 접근 가능 - 주요 입력 항목의 설명 및 도움말 제공(툴팁 등), 필수값 입력 강제 등의 검증 기능 - 사용자 편의성을 보장하는 UI/UX 제공 - 사용자 중심의 UI/UX 설계 ○ 외부망 웹페이지는 협력사의 다양한 PC환경 및 모바일 브라우저를 고려하여 반응형(또는 모바일웹) 등 최적화된 UI/UX를 제공 ○ 전사 UI/UX 표준화를 위한 가이드라인 및 디자인을 제시하여 타 시스템 간 시각적·기능적 통일성을 확보하고 유사한 사용자 경험을 제공
B39: 산출정보 | D39: =VLOOKUP(D35, '3. 요건기술서 전체'!$B:$L, 9, 0) -> 메뉴 목록 및 응용기능 차트, 메뉴 구성도, 화면설계서, UI/UX 표준화 계획(안) | H39: 메뉴 목록 및 응용기능 차트, 메뉴 구성도, 화면설계서
B40: 관련 요구사항 | D40: =VLOOKUP($D35,'3. 요건기술서 전체'!$B:$L,2,0) -> 0 | H40: 0
B42: 요구사항 분류 | D42: 기능 요구사항 | E42: 응락수준 | F42: =VLOOKUP($D43,'3. 요건기술서 전체'!$B:$L,6,0) -> 필수 | H42: 기능 요구사항
B43: 요구사항 고유번호 | D43: =LEFT(D35,3)&"-"&TEXT(VALUE(RIGHT(D35,3))+1,"000") -> SFR-005 | E43: 모바일 | F43: =IFERROR(TRIM(IF(VLOOKUP($D43,'3. 요건기술서 전체'!$B:$L,10,0)<>"",IF(VLOOKUP($D43,'3. 요건기술서 전체'!$B:$L,10,0)="O", "한난O", IF(VLOOKUP($D43,'3. 요건기술서 전체'!$B:$L,10,0)="X", "한난X", "")),"") & " " &IF(VLOOKUP($D43,'3. 요건기술서 전체'!$B:$L,11,0)<>"",IF(VLOOKUP($D43,'3. 요건기술서 전체'!$B:$L,11,0)="O", "외부O", IF(VLOOKUP($D43,'3. 요건기술서 전체'!$B:$L,11,0)="X", "외부X", "")),"")),"") -> 한난O 외부X | H43: SFR-005
B44: 요구사항 명칭 | D44: =VLOOKUP($D43,'3. 요건기술서 전체'!$B:$L,5,0) -> 기능위치마스터 관리 | H44: 기능위치마스터 관리
B45: 요구사항 상세설명 | C45: 정의 | D45: =VLOOKUP($D43,'3. 요건기술서 전체'!$B:$L,7,0) -> 기능위치 관리 | H45: 기능위치 관리
C46: 세부내용 | D46: =VLOOKUP($D43,'3. 요건기술서 전체'!$B:$L,8,0) -> ○ 기능위치마스터 관리 - 계층(Hierarchy)형 구조의 기능 위치 관리 및 표시 기능 - 기능위치 등록/수정 등 이력 관리 기능 - 각 기능위치별 명칭, 코드, 속성, 설명 등의 관리 기능 - 각 수준(Level)에 설비마스터 등록(배치)/수정 등 관리 기능 - 기능위치마스터 중복 등록 방지 및 오류 방지 기능(AI 기술 활용 등 제안사 특화 기능 제시) - 설비마스터 등록(배치)/수정/삭제 이력 관리 기능 (CNR-002) - 19개 지사 공통 기능위치 및 개별 기능위치를 포함하는 기능위치 표준화 방안 제시 | H46: ○ 기능위치마스터 관리 - 계층(Hierarchy)형 구조의 기능 위치 관리 및 표시 기능 - 기능위치 등록/수정 등 이력 관리 기능 - 각 기능위치별 명칭, 코드, 속성, 설명 등의 관리 기능 - 각 수준(Level)에 설비마스터 등록(배치)/수정 등 관리 기능 - 기능위치마스터 중복 등록 방지 및 오류 방지 기능(AI 기술 활용 등 제안사 특화 기능 제시) - 설비마스터 등록(배치)/수정/삭제 이력 관리 기능 (CNR-002) - 19개 지사 공통 기능위치 및 개별 기능위치를 포함하는 기능위치 표준화 방안 제시
...

Sheet 3. 요건기술서 전체
A1: ■ 시스템 기능별 세부 활동단위 정의
A2: ID | E2: Level 1. 단위업무 시스템 | F2: Level 2. 시스템 주요 기능 | G2: 응락수준 | H2: 정의 | I2: 요구사항 상세설명 | J2: 산출정보 | K2: 모바일 | M2: 참고자료 (TO -BE모델 정의서, 건설정보시스템 RFP 등) | N2: 비고
A3: 요구사항 분류 | B3: 요구사항 고유번호 | C3: 관련 요구사항 고유번호 | D3: 관련 요구사항 명칭 | E3: (구분) | F3: (요구사항 명칭) | K3: 한국지역난방공사 | L3: 외부(협력사/시공사 등)
A4: ECR | B4: =A4&"-"&TEXT(COUNTIF($A$4:$A4, A4), "000") -> ECR-001 | D4: =IFERROR(VLOOKUP(C4,B:F,5,0),"") | E4: 시스템 요구사항 | F4: 공통기능 -인프라 구성 표준 | G4: 필수 | H4: 인프라 구성 표준 | I4: ○ IT 인프라 구성 표준 - OS : RHEL 9.4 이상 - JDK : OpenJDK 17 이상 - WEB : nginx 1.28 이상 - WAS : Tomcat 9 이상 - DB : Oracle 19c (Standard) ○ 개발환경 구성 표준 - 전자정부프레임워크 기반 개발환경 준수 ○ IT 인프라 구성 표준 준수 시, 우리 공사의 가상서버 제공 및 운영 지원 ○ IT 인프라 구성 표준 및 개발환경 구성 표준 미준수 시, 제안사 직접 납품 및 운영·유지보수 방안 제시 필수 ○ WEB/WAS/DB 등의 운영 Port는 우리 공사가 지정한 Port로 변경 운영 필수(Well -Known Port 사용 불가) ○ 우리 공사 직원의 업무환경인 가상 데스크탑 환경(VDI. 이하, 내부 업무환경)에서 속도 저하 및 지연없이 모든 서비스 제공 ○ Microsoft Edge 브라우저에서 추가 프로그램(플러그인 등) 설치없이 모든 기능 제공 | J4: 아키텍쳐 설계서 | M4: XI. 시스템 구성도(IT 인프라)
A5: SFR | B5: =A5&"-"&TEXT(COUNTIF($A$4:$A5, A5), "000") -> SFR-001 | D5: =IFERROR(VLOOKUP(C5,B:F,5,0),"") | E5: 공통 | F5: 공통기능 -계정 및 권한 | G5: 필수 | H5: 계정 및 권한 | I5: ○ 계정 및 권한관리 - 로그인 계정별 관리자 권한과 사용자 권한 관리 기능 - 관리자 권한으로 권한 그룹 관리 및 주요 시스템 설정 수행 - 사용자별 권한 및 역할에 따른 관리 기능(메뉴접근/승인/조회/공사/작업/예약/주요정보 등) - 외부 협력사 계정은 계약 기간에 따른 '사용 유효기간(Expiry Date)' 설정 기능을 필수 제공하고, 기간 만료 시 자동 잠금(Lock) 처리되어야 함 - 계약 만료일 이전에 사전 만료일 통보 및 자동 연장 기능 제공 ○ 로그인 시 보직 선택 기능 제공 - 인사 시스템의 '부서' 정보만으로는 사용자의 구체적인 수행 업무(기계/전기/제어/안전 등)를 식별할 수 없으므로, 최초 로그인 또는 권한 변경 필요 시 사용자가 자신의 '보직(Role)'을 직접 선택할 수 있는 팝업 화면을 제공해야 한다. ○ 보직 선택에 따른 권한 자동 매핑 - 사용자가 선택한 보직에 따라, 사전에 정의된 '권한 그룹(Role)'과 '메뉴 접근 권한'이 즉시 시스템에 반영되어야 한다. ○ 다중 보직 및 겸직 지원 - 2개 이상의 보직을 수행하는 겸직 사용자(파견 등) 를 위해, 로그인 후에도 상단 메뉴바 등을 통해 보직(Workspace) 전환이 가능하도록 구현해야 한다. ○ 보직 변경 이력 관리 - 사용자가 보직을 선택하거나 변경한 이력(변경일시, 변경 전/후 보직, 접속 IP 등)은 시스템에 기록 및 보관되어야 한다. ○ 동일 ID 중복 역할인 경우, 한 번에 처리 - 두 가지 이상 직책을 동일 직원이 중복해서 맡을 경우, 중복업무를 한 번에 처리(동일 ID로 검토 시 동일 문건 중 한 건이 처리되면 다른 건도 자동으로 처리) EX) (당초) 홍길동 기안 – 홍길동 팀장 – OOO 부장 -> (변경) 홍길동 기안 – (생략) – OOO 부장 ○ Project OBS 설정 방법 - 인사발령 등으로 인한 변경시 즉시 반영될 수 있도록 OBS(Organization Breakdown Structure) 설정 방법에 대한 개선 - 관리자가 변경되는 조직에 맞게 OBS를 유동적으로 변경할 수 있도록 설정 가능 | J5: 메뉴구성 및 권한정의서 | M5: I. 스마트 유지보수, 자재관리 시스템
A6: SFR | B6: =A6&"-"&TEXT(COUNTIF($A$4:$A6, A6), "000") -> SFR-002 | D6: =IFERROR(VLOOKUP(C6,B:F,5,0),"") | E6: 공통 | F6: 공통기능 -모바일 | G6: 필수 | H6: 모바일 공통 기능 | I6: ○ 모바일 공통 기능 - 기능 요구사항에서 '모바일'로 표시된 기능은 내부 직원 및 외부(협력사/시공사 등) 직원으로 구분하여 모바일에서 제공 - 모바일은 Android OS 와 iOS 를 지원 - 사용자별 권한 및 역할에 따른 승인 처리 기능 - 승인/이상/공사/작업/예약/주요정보 등의 알림(알람)을 모바일 PUSH로 제공 ○ 모바일 기능은 개인 모바일, 지급형 단말기(내부망 접근) 구성으로 분리하여 제공 - 시스템은 사용자가 접속한 단말기 유형(개인용/지급형)과 네트워크(외부망/내부망)을 자동식별하여, 그에 맞는 메인화면과 메뉴트리를 동적으로 구성 ○ 모바일 기능은 우리 공사에서 기 운영 중인 '스마트 안전관리' 모바일 앱과 분리하여 별도로 운영할 수 있는 방안 제안 필수 ○ 모바일 기능은 우리 공사의 보안등급(C -Classified, 기밀/S -Sensitive, 민감/O -Open, 공개)을 준용하여 보안성 검토를 받아야 한다 ○ 모바일 기능은 모바일 환경(개인모바일, 지급형 단말기) UI/UX 최적화 ○ 네트워크 음영지역(지하 공동구 등)에서도 점검 결과 입력 및 조회가 가능하도록 오프라인 모드(Data Caching & Sync) 기능 필수 제공 ○ 모바일 보안을 위해 화면 캡처 방지, 루팅 감지 등 공사 모바일 보안 가이드라인 준수 및 MDM 연동 지원 ○ 하이브리드/웹 표준 기반 디바이스 제어: 모바일 웹 환경에서도 현장 업무 처리를 위해 스마트폰의 카메라, GPS, 파일 시스템에 직접 접근할 수 있는 Web API 또는 하이브리드 브릿지 기술을 적용해야 한다. ○ QR/바코드 스캔 및 처리: 별도의 스캐너 장비 없이 스마트폰 카메라를 통해 자재/설비의 QR(바코드)를 인식하고, 즉시 해당 정보 조회 화면으로 이동하거나 데이터를 입력하는 기능을 제공해야 한다. ○ 현장 사진 촬영 및 최적화: 현장에서 점검/보수 내역 작성 시 카메라를 호출하여 사진을 촬영하고, 서버 전송 용량 최적화(리사이징/압축) 후 즉시 첨부하는 기능을 제공해야 한다. ○ 위치 기반(GPS) 작업 통제: 작업자가 실제 현장에 도착했는지 확인하기 위해 GPS 좌표를 수집한다.(GPS 수집 대상 단말기와 대상은 구축시 협의) | M6: I. 스마트 유지보수, 자재관리 시스템
A7: SFR | B7: =A7&"-"&TEXT(COUNTIF($A$4:$A7, A7), "000") -> SFR-003 | D7: =IFERROR(VLOOKUP(C7,B:F,5,0),"") | E7: 공통 | F7: 공통기능 -정보 조회 | G7: 필수 | H7: 정보 조회 기능 | I7: ○ 정보 조회 기능 - 로그인한 사용자의 소속 지사를 기준으로 자재·설비·작업·공사 등의 정보 조회 - 모든 정보는 사용자의 조회 조건에 따라 소속 지사 정보와 타지사 정보 조회 가능 - 조회 결과로 표시되는 모든 항목에 대해 조회 조건을 설정할 수 있어야 하며, 문자열·숫자·날짜·부울값 등의 범위·값·포함여부조건 등 설정 기능 - 모든 항목에 대한 조건 검색 시, 대용량 데이터 조회 속도 보장을 위한 서버 사이드(Server-side) 필터링 및 인덱싱 최적화 방안 제시 - 협력사 사용자의 메뉴 접근 및 메뉴별 정보 조회·등록·수정 등 권한 설정 기능 - PDF/이미지 파일 등은 다운로드 및 브라우저에서 직접 보기 기능 직접보기 기능 구현을 위한 상용 뷰어 솔루션은 직접구매 제공 예정이며, 시스템과 연계 및 최적화 지원 - 모든 조회 결과는 엑셀 다운로드 기능 제공(모바일 환경 시, 다운로드 기능 제외) - 승인이 필요한 업무의 경우, 승인선관리/진행단계표시/승인/반려 등의 정보 조회 기능(시스템 內 승인 처리 기능) - 우리 공사 전자결재를 활용한 승인 업무의 경우, 전자결재 연계 처리 및 진행상태 조회 기능 - 업무별 우리 공사 보고서 양식을 준수하는 출력 기능 제공 ○ 모바일 기능은 개인 모바일, 지급형 단말기(내부망 접근) 접근에 따라 정보 조회 및 권한 차등 적용 - 개인용 : 보안과 무관한 일반업무 위주의 경량화된 UI 제공(현장점검 입력, 로그시트입력, TM발행, 현장사진 업로드 기능 등) - 지급형 : 현장점검, 설비 및 도면 조회 등 핵심업무 수행을 위한 데이터 중심 UI 제공(VPN 및 공사 보안 규정 및 국정원 가이드라인 준수) ○ 통계 기능 - 주요 기능 및 업무에 대한 통계 정보 제공(통계 대상 및 범위는 사업 수행 시, 협의) - 관리자 또는 사용자의 통계 정보 범위, 대상, 결과, 차트 등의 변경/설정 기능 제공 | M7: I. 스마트 유지보수, 자재관리 시스템
A8: SFR | B8: =A8&"-"&TEXT(COUNTIF($A$4:$A8, A8), "000") -> SFR-004 | D8: =IFERROR(VLOOKUP(C8,B:F,5,0),"") | E8: 공통 | F8: 사용자 인터페이스(UI/UX) | G8: 필수 | H8: 사용자 인터페이스(UI/UX) | I8: ○ 사용자 인터페이스 - 목록 정보는 그리드 형태로 표시하며, 각 열의 그리드 헤더에서 조회 조건(문자열·숫자·날짜·부울값 등) 범위·값·포함여부조건 등 설정 기능 - 조회 결과는 일정량을 우선 표시하고, 스크롤 시 조회 결과 추가(Fetch) 또는 기능 - 조회 결과에서 특정 열 선택 시, 새창/새탭/팝업 등으로 상세 정보 및 연관 정보 표시 기능 - 탭의 경우, 새탭 생성 시 최초 로딩 이후 탭 간 이동 시 로딩 제거(탭별 사용자 새로고침에 의한 로딩) - 탭 방식 인터페이스 구현 시, 다중 탭 오픈에 따른 클라이언트(VDI 환경 포함) 메모리 점유율 최적화 방안(비활성 탭 리소스 관리 등) 제시 - 사용자 즐겨찾기 메뉴 구성 기능 - 사이드 메뉴/상단 메뉴 등 화면을 구성하는 주요 콤포넌트의 보이기/숨기기 기능 - 주요 알림 및 긴급 알람 등은 모든 메뉴의 공통 영역에서 실시간 표시(숫자/리스트/요약정보/상세정보 등)하고 상시 관련 정보 접근 가능 - 주요 입력 항목의 설명 및 도움말 제공(툴팁 등), 필수값 입력 강제 등의 검증 기능 - 사용자 편의성을 보장하는 UI/UX 제공 - 사용자 중심의 UI/UX 설계 - 사용자는 End to End 로 업무프로세스가 진행되는것 을 확인할 수 있도록 상단에 현재 업무과정을 표기하여야한다. - 상단의 업무프로세스 UI를 클릭스 타 레거시의 해당 메뉴로 진입할 수 있도록 URL을 연결한다. - 상단의 업무프로세스 과정에서 타부서의 결재 과정이나, 시스템의 오류사항을 수시로 점검하여 반영한다. ○ 외부망 웹페이지는 협력사의 다양한 PC환경 및 모바일 브라우저를 고려하여 반응형(또는 모바일웹) 등 최적화된 UI/UX를 제공 ○ 전사 UI/UX 표준화를 위한 웹 디자인을 제시하여 업무시스템간 시각적,기능적 통일성을 확보하고 유사한 사용자 경험을 제공 (HTML5 기반 업무포털과 연계하여 포털 중앙화면에서 통합 제공 등) | J8: 메뉴 목록 및 응용기능 차트, 메뉴 구성도, 화면설계서, UI/UX 표준화 계획(안) | M8: III. 사용자 인터페이스(UI) | N8: 일상감사 사전검토 반영
A9: SFR | B9: =A9&"-"&TEXT(COUNTIF($A$4:$A9, A9), "000") -> SFR-005 | C9: =B142 -> CNR-002 | D9: =IFERROR(VLOOKUP(C9,B:F,5,0),"") -> 설비 표준화 및 DB화 | E9: 설비관리 | F9: 기능위치마스터 관리 | G9: 필수 | H9: 기능위치 관리 | I9: ○ 기능위치마스터 관리 - 계층(Hierarchy)형 구조의 기능 위치 관리 및 표시 기능 - 기능위치 등록/수정 등 이력 관리 기능 - 각 기능위치별 명칭, 코드, 속성, 설명 등의 관리 기능 - 각 수준(Level)에 설비마스터 등록(배치)/수정 등 관리 기능 - 기능위치마스터 중복 등록 방지 및 오류 방지 기능(AI 기술 활용 등 제안사 특화 기능 제시) - 설비마스터 등록(배치)/수정/삭제 이력 관리 기능 (CNR-002) - 19개 지사 공통 기능위치 및 개별 기능위치를 포함하는 기능위치 표준화 방안 제시 | K9: O | L9: X | M9: VII. 설비관리
A10: SFR | B10: =A10&"-"&TEXT(COUNTIF($A$4:$A10, A10), "000") -> SFR-006 | C10: =B142 -> CNR-002 | D10: =IFERROR(VLOOKUP(C10,B:F,5,0),"") -> 설비 표준화 및 DB화 | E10: 설비관리 | F10: 설비마스터 관리 | G10: 필수 | H10: 설비마스터 및 설비그룹 관리 | I10: ○ 설비마스터 관리 - 설비마스터 등록/수정 기능(기본정보, 기술정보, 자산정보, 상세정보, 속성정보 등) - 설비마스터 등록/수정 등 이력 관리 기능 - 설비마스터 필수 속성정보의 입력 누락/오기입 방지 유효성 검증 기능 - 설비마스터 중복 등록 방지 및 기능위치 배치 오류 방지 기능(AI 기술 활용 등 제안사 특화 기능 제시) - 설비마스터 속성 정보 중 자재교체 일정, 예방점검 일정 등 주요 일정 도래 시, 알람 발생 기능 - 다수의 연관된 설비마스터로 구성된 설비그룹 관리 기능 - 설비마스터와 연관된 차단기 및 밸브 정보 관리 기능 ○ 기능위치를 활용한 설비마스터 조회 - 기능위치에서 특정 수준(Level) 선택 시, 해당 수준 및 하위 수준에 속한 설비마스터 목록 조회 및 상세 정보 조회 기능 ○ 설비마스터 상세정보 조회 - 설비번호, 설비명, 태그번호, 기능위치명, 설비종류, 상태, 도면번호 등 모든 설비마스터 관리 속성 조회 제공 - TM 이력, Red Tag 이력, 작업이력, 고장이력, 자재사용이력, 설비 BOM, 설계기준서 등 설비마스터와 연관된 정보 조회 기능(새창/새탭/팝업/영역구분 등) - 설비마스터 변경이력(변경자, 변경일시, 변경사유 등) 조회 기능 - 설비마스터와 연관된 스마트 도면 및 일반 문서도면, 기술문서 등 조회 기능 (CNR-002) - 설비마스터 분류체계, 코드체계, 관리속성, 식별체계, 표기표준 등을 포함하는 설비마스터 표준화 방안, DB화 방안 제시 및 수행 용역 포함 (CNR-002) - 19개 지사 설비 현장/현황 조사 및 DB화 용역 포함 | K10: O | L10: O | M10: VII. 설비관리
A11: SFR | B11: =A11&"-"&TEXT(COUNTIF($A$4:$A11, A11), "000") -> SFR-007 | C11: =B142 -> CNR-002 | D11: =IFERROR(VLOOKUP(C11,B:F,5,0),"") -> 설비 표준화 및 DB화 | E11: 설비관리 | F11: 설비 BOM 관리 | G11: 필수 | H11: 설비 BOM 관리 | I11: ○ 설비 BOM 관리 - 설비를 구성하는 설비 BOM(자재마스터/자재패키지 및 구성 수량) 등록/수정/삭제 기능 및 이력관리 기능 - 설비 BOM 생성 시, 동일 설비마스터 또는 유사 설비마스터의 설비 BOM 복제 기능 (CNR-002) - O/H(정기점검보수공사) 대상 설비마스터의 설비 BOM 구성, DB화 방안 제시 및 수행 용역 포함 | K11: O | L11: X | M11: VII. 설비관리
A12: SFR | B12: =A12&"-"&TEXT(COUNTIF($A$4:$A12, A12), "000") -> SFR-008 | D12: =IFERROR(VLOOKUP(C12,B:F,5,0),"") | E12: 스마트도면 | F12: 스마트 도면 관리 기능(공통) | G12: 필수 | H12: 스마트 도면 관리 기능(공통) | I12: ○ 스마트 도면관리 - 동일 시스템에서 기능을 제공하거나, 별도 시스템으로 기능 제공 가능 - 별도 시스템으로 기능 제공 시, 정보 연계 방안 제시 필수 - 스마트 도면 內, 설비별 실시간 운전 정보 연계 방안 제시 - 스마트 도면의 접근/조회(View)/편집(Edit)/정보수정 등에 필요한 계정 관리 및 권한 관리 기능 제공 - 스마트 도면 조회/편집/정보수정 시, 추가 프로그램 및 플러그인 설치없이 웹 브라우저에서 모든 기능 사용 필수 - 스마트 도면 外, 사용자가 등록한 기타 도면(비전산화 대상 도면) 관리 기능(최신도면제공 및 이력관리) - 스마트 도면의 태그를 활용한 설비마스터(설비명, 설비정보, 정비이력 등) 정보 연결, Red Tag 설계 기능 ○ 전산화(지능화) 도면 外 건설 관련 도면 등 사용자가 선택한 dwg. pdf 도면에 대한 조회(View) 및 편집(Edit), 마킹 기능 제공 - 도면 Mark up 및 편집시 자주 사용하는 아이콘(밸브 닫힘, 열림, 차단기 조작 등)을 제공 ○ PC 및 모바일 환경 지원 - PC 및 모바일(지급형 태블릿)에서 스마트 도면 조회/편집/정보수정 기능 제공 - PC : Microsoft Edge 브라우저에서 모든 기능 제공 - 모바일(지급형 태블릿)에서 도면 접근 시, 우리 공사 MDM(Mobile Device Management) 프로그램 구동 필수 - 모바일 : 기기의 종류 및 해상도에 따라 화면 배치(레이아웃) 등의 유동적 변경 기능 ○ 타 플랫폼간 연계방안 - 스마트 안전관리 플랫폼 정보 연계 | K12: O | L12: X | M12: VI. 스마트 도면관리
A13: SFR | B13: =A13&"-"&TEXT(COUNTIF($A$4:$A13, A13), "000") -> SFR-009 | C13: =B142 -> CNR-002 | D13: =IFERROR(VLOOKUP(C13,B:F,5,0),"") -> 설비 표준화 및 DB화 | E13: 스마트도면 | F13: 스마트 도면 전환 | G13: 필수 | H13: 스마트 도면 전환 | I13: ○ 도면 전산화(지능화) - PDF 또는 이미지 형식의 도면(대상 : P&ID 및 SLD)에서 Tag No, 파이프, 펌프, 설비 BOM 등의 주요 정보 추출, 이를 스마트 도면으로 전환 - 도면 전산화 기술(AI/OCR 등) 제시 - 파일 형태의 관리가 아닌 DB 형태의 스마트 도면 관리 기능 - 도면 전산화 중 발생한 오류/오차 등의 수정 기능 - 향후 추가되는 신규 도면 등록 시, 스마트 도면으로 전환 가능하도록 사용자 맞춤형 기능 제공 ○ 도면 전산화에 필요한 용역 비용 및 방법 제시 - 대상 도면 수 : 5,000 장 ○ 공사 현재 관리중인 비전산화 도면에 대한 관리방안 제시(파일 및 수정이력 관리 등) (CNR-002) - Tag No, 설비 연관 정보, 설비 BOM(자재 리스트 및 수량), 기타 속성 및 단위 정보 등 추출 및 DB화 | M13: VI. 스마트 도면관리
A14: SFR | B14: =A14&"-"&TEXT(COUNTIF($A$4:$A14, A14), "000") -> SFR-010 | D14: =IFERROR(VLOOKUP(C14,B:F,5,0),"") | E14: 스마트도면 | F14: 스마트 도면 편집(Edit) 기능 | G14: 필수 | H14: 스마트 도면 편집(Edit) 기능 | I14: ○ 도면 편집(Edit) 및 설비마스터 정보 매핑(Mapping) - 설비마스터와 연관된 스마트 도면 제공 - 사용자 권한에 따른 도면 편집 기능 활성화/비활성화 - 쉽고 직관적인 도면 편집 기능 - 우리 공사의 도면번호 관리기준 및 Tag 관리 기준, 속성정보 기준 등 준수 - 도면을 구성하는 모든 구성요소는 기능위치, 분류체계 등 우리 공사 관리 기준을 반영한 계층형 관리 구조 지원 - 도면을 구성하는 모든 구성요소 간 연관관계 관리 기능 - 도면 편집 시, 버전관리/승인/편집자 등의 이력정보와 버전 관리 기능 제공 - 도면 편집 이후, 연관 담당자의 승인 후 반영 기능(도면관리 기준(안) 제시) - 도면 편집 시 동시 수정 방지를 위한 '체크인/체크아웃(Check -in/out)' 또는 '편집 잠금(Locking)' 기능을 필수 제공해야 함. - 도면 내 설비 객체와 설비마스터 DB 간의 '양방향 동기화(Bi -directional Sync)' 또는 '무결성 검증 리포트' 기능을 제공하여 데이터 불일치를 방지해야 함 | K14: O | L14: X | M14: VI. 스마트 도면관리
A15: SFR | B15: =A15&"-"&TEXT(COUNTIF($A$4:$A15, A15), "000") -> SFR-011 | D15: =IFERROR(VLOOKUP(C15,B:F,5,0),"") | E15: 스마트도면 | F15: 스마트 도면 보기(View) 기능 | G15: 필수 | H15: 스마트 도면 보기(View) 기능 | I15: ○ 도면 조회(View) - 설비마스터와 연관된 도면 접근 기능 - 사용자 권한에 따른 도면 접근 및 조회 - 도면 조회 시, 확대(Zoom), 회전(Pan), 강조(Highlight), 선택(Selection) 등의 기능 제공 - P&ID 및 SLD 의 Tag 및 속성 정보 등의 검색 기능 - Tag No. 기준으로 기타 도면 및 문서 등의 연계 조회 기능 - 전산화된 모든 도면은 파일 다운로드 없이 웹 브라우저 상에서 조회 - 도면 조회 시, 사용자 권한에 따라 편집 기능으로 전환 기능 - 권한에 따른 담당자 노트(Remark) 생성 기능(노트 추가는 도면 버전 관리에서 제외) - 웹 기반 도면 뷰어 도입 시, 벡터(Vector) 방식 렌더링을 지원하여 확대 시에도 깨짐이 없어야 하며, 대용량 도면 로딩 시 타일링(Tiling) 기술 등을 통해 3초 이내 조회 성능을 보장해야 함. ○ 스마트 도면 外, 사용자가 등록한 기타 문서 보기 기능 ○ Multi Window 기능 추가 (여러개의 창을 열어서 동시에 도면 확인 가능) | K15: O | L15: X | M15: VI. 스마트 도면관리
A16: SFR | B16: =A16&"-"&TEXT(COUNTIF($A$4:$A16, A16), "000") -> SFR-012 | C16: =B143 -> CNR-003 | D16: =IFERROR(VLOOKUP(C16,B:F,5,0),"") -> 자재 표준화 및 DB화 | E16: 자재관리(공통) | F16: 자재마스터 관리 | G16: 필수 | H16: 자재마스터 관리 | I16: ○ 자재마스터 관리 - 자재마스터 관리 대상 : 열원/열수송/열량계 - 자재마스터 등록/수정/조회 기능(기본정보, 기술정보, 자산정보, 상세정보, 속성정보 등) - 자재마스터 등록/수정 등 이력 관리 기능 - 재고자산이 존재하지 않는 자재마스터의 미사용 처리 기능 - 자재마스터 정보는 SAP 자재마스터에 실시간 정보 연계 - SAP 자재마스터의 관리 항목 外, 별도 항목 관리 기능 - 자재마스터 필수 속성정보의 입력 누락/오기입 방지 유효성 검증 기능 - 자재마스터 중복 등록 방지 기능(AI 기술 활용 등 제안사 특화 기능 제시) - 자재 중복 방지를 위한 AI 기술 적용 시, 단순히 이름만 비교하는 것이 아니라 속성(Spec) 값의 유사도까지 비교하는 알고리즘을 제안해야 함. - 다수의 자재마스터와 구성 수량을 관리하는 자재 패키지/세트 기능 - 자재마스터와 연관된 설비마스터/작업이력/공사이력 등의 조회 기능 (CNR-003) 자재마스터 분류체계, 관리 속성정보, 코드체계, 식별체계, 표기표준, 단위표준 등의 표준화 및 DB화 | K16: O | L16: X | M16: V. 자재관리
A17: SFR | B17: =A17&"-"&TEXT(COUNTIF($A$4:$A17, A17), "000") -> SFR-013 | C17: =B143 -> CNR-003 | D17: =IFERROR(VLOOKUP(C17,B:F,5,0),"") -> 자재 표준화 및 DB화 | E17: 자재관리(공통) | F17: 자재관리 | G17: 필수 | H17: 자재관리(공통) | I17: ○ 자재관리(공통) - 자재·공기구 구매요청/재고/전용/환입/불용 등의 처리 기능 - 자재관리 기능은 SAP 와 실시간 정보 연계(SAP 관리 영역 外 정보는 연계 제외) - 자재관리(회계, 재무)를 위한 통계분석 기능(SAP 연계 필수) - 건설공사 등 준공을 위한 자재 정산(부분, 종합) 기능 - 필요 시 전자계약 및 전자결재 등과의 실시간 정보 연계 - SAP 자산관리번호(이하, 자산번호)를 활용한 개별자재 관리 기능(1자재 1태그) - 개별자재 대상 : 예비품, 저장품, 수리부분품, 비저장품, 보수소모품, 사급자재 - 지사 -자재마스터 -자산번호 -구매번호 -개별자재 등의 연관 정보를 관리 - 소속지사 外, 타지사 자재 조회 기능 - 지사 창고별 자재재고/가용재고/안전재고 수량 조회 기능 - 사용자 지정 자재별 재주문 필요 시점 설정 관리 및 알림 기능 - 개별자재를 위한 QR 코드 발행·출력 기능(QR 코드에는 시스템 식별자만 인코딩) - 개별자재 QR 코드 발행 대상 : 열원/열량계 - 검토사항 : 정확한 자재의 수량 및 범위 확정 필요 - QR 코드 출력 이력 관리 기능 - QR 코드 프린터(19ea, 19개 지사 창고 비치) 및 QR 코드 출력용지(지사별 자재 10,000개 대상) 납품 포함 (QR 프린터) - Thermal Transfer(열전사) 방식 지원, 해상도 300dpi 이상, 최대 인쇄폭 104mm 이상, 인쇄속도 150mm/s 이상, USB 및 Ethernet 인터페이스 제공, 라벨인쇄를 위한 Gap 및 Black Mark 센서 지원, 표준 프린팅 언어(ZPL/EPL/TSPL 중 1개 이상) 또는 동급의 외부 연동 인터페이스를 제공, 리본 왁스레진/레진 등급 사용 가능, 합성지(PP/PET) 라벨 인쇄 지원) - QR 코드는 프린터와 모바일 장비를 OTG(On -The -Go)로 연결하여 출력 ※ 공사 보안규정상 건물 내 WIFI 연결이 불가. - 모바일 장비에서 재물조사 대상 자재조회 후, QR 코드 인식으로 재물조사 처리 기능(다수·동일 자재의 경우 수량으로 일괄처리) - 모바일 앱에서 QR 코드 인식 시, 자재 상세정보 제공 기능 (CNR-003) - 개별자재에 QR 코드 출력 및 부착 용역 포함(부착 불가 시, 고리형 부착 등의 방법 제시) (CNR-003) - 재고자재 실물 현장/현황 조사 및 DB화 용역 포함 | K17: O | L17: O | M17: V. 자재관리
A18: SFR | B18: =A18&"-"&TEXT(COUNTIF($A$4:$A18, A18), "000") -> SFR-014 | C18: =B143 -> CNR-003 | D18: =IFERROR(VLOOKUP(C18,B:F,5,0),"") -> 자재 표준화 및 DB화 | E18: 자재관리(공통) | F18: 자재 입·출고관리 | G18: 필수 | H18: 자재 창고관리(공통) | I18: ○ 자재 입·출고(공통) - 자재 검수/입고/출고예약/출고 관리 기능(모바일 장비 및 자재 QR 코드 활용 지원, SAP 실시간 연계) - 다수의 자재 입·출고 시, 일괄처리 기능 - 자재 입·출고 내역 수정 기능(재고 수량 원상복구) - 입출고 내역 수정(취소)은 '결재 승인'을 통해서만 가능하도록 하고, 수정 사유와 수정 전/후 데이터를 감사 로그(Audit Log)로 영구 보관해야 함. - 창고 및 보관위치 관리 기능 (CNR-003) - 창고 및 보관위치 QR 코드 발행 및 부착 용역 포함 | K18: O | L18: O | M18: V. 자재관리
A19: SFR | B19: =A19&"-"&TEXT(COUNTIF($A$4:$A19, A19), "000") -> SFR-015 | D19: =IFERROR(VLOOKUP(C19,B:F,5,0),"") | E19: 자재관리(열원) | F19: 열원 자재관리 | G19: 필수 | H19: 열원 자재관리 | I19: ○ 자재관리(열원) - 자재마스터 기본 속성에서 사용하는 교체주기 속성 外, 자재별 사용자 지정 교체주기/점검주기 관리 및 주기 도래 시, 알림 기능 - 자재마스터별 정수관리/자재재고 등 관리 기능 ○ 자재관리(열원 - 고온부품) - 고온부품별 장착/탈착/재생/비용/EOH현황 등의 관리 및 이력관리 기능 - 고온부품 Set 구성 및 재고관리 기능 - 고온부품별 EOH 계산 기준(기동/정지 횟수별 가중치 등) 관리 기능 -EOH 계산 로직은 소스 코드가 아닌 '수식 관리 엔진(Rule Engine)' 형태로 구현하여, 현업 담당자가 가중치나 계산식을 직접 설정/변경할 수 있도록 유연성을 확보해야 함. - EOH 기반 잔여 수명 예측 및 알림 기능 ○ 자재관리(열원 - 공기구) - 공기구 대여/반납/반납지연/검교정/불용처리/전용 등의 관리 및 이력관리 기능 - 검교정 필요 공기구의 교정주기/교정일자/계획/결과/차기예정일 등 관리 기능 - 공기구 중 특수 공기구(Special Tool) 관리 기능 ○ 자재관리(열원 - 수출입통관관리) - 고온부품 등 수출입통관에 필요한 회계처리 지원(SAP 수입통관 연계 업무 : 15개, SAP 수출통관 연계 업무 : 9개) - 관세청 UNI -PASS 와 연계하여 통관진행상태 정보 확인 기능 - UNI -PASS 연동 장애 시 업무 마비를 막기 위해, 통관 정보를 엑셀 업로드나 수기로 등록할 수 있는 백업(Backup) 프로세스를 반드시 구현해야 함. | K19: O | L19: X | M19: V. 자재관리
A20: SFR | B20: =A20&"-"&TEXT(COUNTIF($A$4:$A20, A20), "000") -> SFR-016 | D20: =IFERROR(VLOOKUP(C20,B:F,5,0),"") | E20: 자재관리(열수송) | F20: 열수송 자재관리 | G20: 필수 | H20: 열수송 자재관리 | I20: ○ 자재관리(열수송) - SAP 에서 관리하는 배관자재의 미터(M)단위 합계 관리 外, 개수(EA) 단위 개별 수량 관리 기능(1자재 1태그) - 연도별, 회차별, 지사별 열수송자재 정기발주 및 납품지시 관리 기능 - 임시 자산 등록 후, 일괄 자산 취득 처리 기능 ○ 자재관리(열수송 - 긴급자재보관소) - 우리 공사 및 긴급자재 협약사업자/협력사의 긴급자재보관소 자재조회 및 신청 관리 기능 - 긴급자재 요청에 대한 긴급자재보관소 입·출고/전용/환입/불용 처리 등 우리 공사 처리 업무(전자결재/전자계약/SAP/한난맵 등) 연계 기능 - 긴급자재 협약사를 위한 '외부망 접근환경' 구축 및 내부망 시스템과의 아키텍처를 명시해야 함 | K20: O | L20: O | M20: V. 자재관리
A21: SFR | B21: =A21&"-"&TEXT(COUNTIF($A$4:$A21, A21), "000") -> SFR-017 | C21: =B7 -> SFR-003 | D21: =IFERROR(VLOOKUP(C21,B:F,5,0),"") -> 공통기능 -정보 조회 | E21: 자재관리(열량계) | F21: 열량계 자재관리 | G21: 필수 | H21: 열량계 자재관리 | I21: ○ 자재관리(열량계) - 열량계 규격(유량부/연산부/냉수/중온수), 상태(신품/재제조) 등의 열량계 특성을 반영한 속성정보 관리 기능 - 열량계 검정만료일의 잔여유효기간 알림 기능 - 회차별 신규구매 및 재제조 수량에 대한 신청/조회/확정 기능 - 열량계 구매/검수/입·출고 등의 업무 처리 시, 전자결재/전자계약/SAP 등 실시간 정보 연계 기능 ○ '공통 - 정보 조회 기능' 요구사항의 조회 기능 외, 열량계 속성을 반영한 조회 - 설치/가용재고/출고대기/출고/불용대기/검정만료대상/예비율 등의 상세 조회 조건 설정 기능 - 건물명/건물번호/기계실번호/설치번호/사용자정보 등 열량계 기물정보와 종류별/연도별/고장유형 등의 이력 조회 기능 | K21: O | L21: O | M21: V. 자재관리
A22: SFR | B22: =A22&"-"&TEXT(COUNTIF($A$4:$A22, A22), "000") -> SFR-018 | C22: =B144 -> CNR-004 | D22: =IFERROR(VLOOKUP(C22,B:F,5,0),"") -> 유지보수 표준화 및 DB화 | E22: 작업관리 | F22: 작업오더 조회 및 생성 | G22: 필수 | H22: 작업관리 | I22: ○ 작업오더 관리 - 작업오더 기본정보 및 상세정보(자재, 공량, 경비, Red Tag 등) 관리 기능 - TM/고장속보/예방점검/예방정비 등의 주요 관리 정보와 연계 기능 - 작업오더별 승인/반려 등의 처리/이력 관리 기능 - 작업오더 등록 시, TM 또는 고장속보, 계획예방정비 등 연계 기능 - 작업오더로 등록되지 않은 TM 및 고장속보 등의 알림 기능 - 작업오더의 공량/자재/경비 등의 설계 관리 및 설계금액 자동 산출 기능 - 자재 설계 시, 필요 자재(설비 BOM 정보 활용 또는 사용자 입력)의 재고 수량 및 출고 가능 정보 제공 - 자재의 가용수량 부족 시, 작업오더 임시저장 기능 및 자재 가용 시, 알림 제공 - 설비마스터에 기 등록된 Red Tag 정보 자동 연계 기능(수정 가능) - 설비마스터에 Red Tag 미등록 시, Red Tag 설계 이력 추천/적용 기능(AI 기술 활용 등 제안사 특화 기능 제시) - 필수항목누락/수량/단가입력오류/중복품목방지 등 사용자 입력 오류 검증 및 안내 기능 - 작업오더 신규 생성 시, 설계 기준서 및 작업 설계이력 조회/적용 기능 - 설비별 설계기준서 및 작업오더 설계이력 추천/적용 기능(AI 기술 활용 등 제안사 특화 기능 제시) - 작업종료 후, 내용/결과/실적/사진업로드/기기점검결과보고서/관련자료업로드 등의 정보 관리 기능 - 작업오더로 수행된 예방정비 작업종료 시, 예방정비/예방정비주기/차기예방정비일정 등의 예방정보 업데이트 기능 - 우리 공사 표준시스템인 '스마트 안전관리 플랫폼'과 연계하여 안전작업허가서 관리 - 스마트 안전관리 시스템에서, '안전작업허가서 승인 완료' 신호가 수신되어야만 작업오더를 '착수(Start)' 상태로 변경할 수 있는 프로세스 제어(Interlock) 기능을 구현해야 함. (CNR-004) - 설비별 작업오더 설계이력 표준화 및 DB화 용역 포함(O/H 대상 설비) | K22: O | L22: X | M22: VIII. 유지보수
A23: SFR | B23: =A23&"-"&TEXT(COUNTIF($A$4:$A23, A23), "000") -> SFR-019 | D23: =IFERROR(VLOOKUP(C23,B:F,5,0),"") | E23: 작업관리 | F23: 기기점검결과보고서 | G23: 필수 | H23: 작업관리 - 기기점검결과보고서 | I23: ○ 기기점검결과보고서 관리 - 작업 중 작성하는 기기점검결과보고서 관리 기능 - 점검 보고서 양식을 코딩 없이 현업이 직접 생성/수정할 수 있는 '전자서식 생성기(Form Generator)' 솔루션 또는 기능을 도입해야 함. - 기기점검결과보고서의 승인/반려 등의 처리/이력 관리 기능(알림 발송 포함) - 기기점검결과보고서를 활용한 공사통보서(서브오더, 기존 작업오더의 추가 작업오더) 연계 등록 기능 | M23: VIII. 유지보수
A24: SFR | B24: =A24&"-"&TEXT(COUNTIF($A$4:$A24, A24), "000") -> SFR-020 | D24: =IFERROR(VLOOKUP(C24,B:F,5,0),"") | E24: 작업관리 | F24: 공사기간관리 | G24: 필수 | H24: 작업관리 - 작업연장 | I24: ○ 작업연장 관리 - 진행 중인 작업오더의 기간 연장 관리 기능 - 요청내용/기간/사유/계획대비변동율/근거자료 및 승인/반려 등의 처리/이력 관리 기능 | K24: O | L24: X | M24: VIII. 유지보수
A25: SFR | B25: =A25&"-"&TEXT(COUNTIF($A$4:$A25, A25), "000") -> SFR-021 | D25: =IFERROR(VLOOKUP(C25,B:F,5,0),"") | E25: 작업관리 | F25: 공사통보서 발행 | G25: 필수 | H25: 작업관리 - 공사통보서 | I25: ○ 공사통보서(서브오더, 기존 작업오더의 추가 작업오더) 관리 - 작업오더 수행 중, 추가자재/외주가공/장비임차 등을 관리하는 공사통보서 관리 기능 - 공사통보서의 종류(지입/외주/임차)/통보내용/연계 작업오더/설계내역/설계금액 등의 정보 관리 기능 - 지입/외주/임차 등 각 항목의 수량/단가를 활용한 총금액 자동 처리 기능 - 다수의 기기점검결과보고서 연계 기능 | K25: O | L25: O | M25: VIII. 유지보수
A26: SFR | B26: =A26&"-"&TEXT(COUNTIF($A$4:$A26, A26), "000") -> SFR-022 | D26: =IFERROR(VLOOKUP(C26,B:F,5,0),"") | E26: 작업관리 | F26: 검수 -지입/외주/임차 | G26: 필수 | H26: 작업관리·공사관리(공통) - 지입·외주·임차 관리 | I26: ○ 검수 관리 - 지입·외주·임차 검수 필요 건 조회 및 검수 요청, 검수 결과 입력 기능 - 검수요청 시, 선택한 작업오더(또는 공사통보서) 정보 연계를 통한 자동 입력 기능 - 검수 관련 증빙문서(견적서, 세금계산서, 검수사진, 납품서 등) 첨부/다운로드 기능 - 정비부서 반려 시, 반려 사유 그룹핑 선택 지정 및 상세 반려내용 기록 기능 - 현장 검수 시, 모바일 기기에서 검수 정보 확인, 수량 스캔(바코드/QR), 사진 촬영·첨부, 결과입력, 반려/승인요청 기능 제공 | K26: O | L26: O | M26: VIII. 유지보수
A27: SFR | B27: =A27&"-"&TEXT(COUNTIF($A$4:$A27, A27), "000") -> SFR-023 | D27: =IFERROR(VLOOKUP(C27,B:F,5,0),"") | E27: 작업관리 | F27: 공사마스터 | G27: 필수 | H27: 공사마스터 관리 | I27: ○ 공사마스터 관리 - 공사종류/기간/금액 등의 공사 일반정보와 공사오더로 구성된 공사마스터 관리 기능 - 공사일반/공사비/추정가격/정산/설계변경/준공/기성/검수 등의 정보 관리 기능 - 공사마스터와 연관된 공사오더에 공통 적용 가능한 항목(보증기간, 노임단가, 간접노무비 등) 관리 기능 - 공사마스터 정보 관리 시, 연관된 공사오더 설계 정보 확인 편의성 제공 - 제비율 관리 기능(법규/공사 등의 기준 전산화 및 선택) - 물가정보 관리 기능 - 물가정보 및 제비율의 기준 시점 변경 시, 관련된 단가/제비율 일괄 적용 기능 - 물가정보/제비율 변경 시, '적용 개시일(Effective Date)' 관리 기능을 두어, 해당 일자 기준 이전/이후 공사오더의 단가가 자동 분리 적용되도록 설계해야 함. - 공사 설계변경, 제비율 기준 변경 등 주요 정보 알림 기능 - 공사오더의 금액을 활용하여 제경비 자동 산출 기능(사용자 지정 산출식 적용 등) - 공사마스터 미사용 처리 시, 공사마스터에 연결된 공사오더 미사용 처리 기능 - 유사 공사마스터 설계 내역 복사 및 일부 정보 복사 기능 - 정산/설계변경/준공검수내역확인 등 내부처리 업무 지원(전자결재/전자계약 등 연계 처리) - 공사마스터 변경 시, 변경 전·후 비교 기능 - 공사오더 실적 기반 집행률/잔액계산 등 비용 정보 확인 기능(계약액 대비) - 공사마스터 변경 시, 기술정산서 관리 기능 - 준공/기성 검사결과 및 검수자료(검사성적서, 사진 등) 관리 기능 - 본사 통합발주(경상정비 공사, 판형열교환기, 유체커플링 등) 공사 설계 및 지사별 사후관리 기능 지원 | K27: O | L27: X | M27: VIII. 유지보수
A28: SFR | B28: =A28&"-"&TEXT(COUNTIF($A$4:$A28, A28), "000") -> SFR-024 | D28: =IFERROR(VLOOKUP(C28,B:F,5,0),"") | E28: 작업관리 | F28: 용역마스터 | G28: 필수 | H28: 용역마스터 관리 | I28: ○ 용역마스터 관리 - 용역종류/기간/금액 등의 용역 일반정보와 용역오더로 구성된 용역마스터 관리 기능 - 용역일반/용역비/추정가격/정산/설계변경/준공/기성/검수 등의 정보 관리 기능 - 제비율 관리 기능(법규/용역 등의 기준 전산화 및 선택) - 물가정보 관리 기능 - 물가정보 및 제비율의 기준 시점 변경 시, 관련된 단가/제비율 일괄 적용 기능 - 물가정보/제비율 변경 시, '적용 개시일(Effective Date)' 관리 기능을 두어, 해당 일자 기준 이전/이후 용역오더의 단가가 자동 분리 적용되도록 설계해야 함. - 용역 설계변경, 제비율 기준 변경 등 주요 정보 알림 기능 - 용역오더의 금액을 활용하여 제경비 자동 산출 기능(사용자 지정 산출식 적용 등) - 용역마스터 미사용 처리 시, 용역마스터에 연결된 용역오더 미사용 처리 기능 - 유사 용역마스터 설계 내역 복사 및 일부 정보 복사 기능 - 정산/설계변경/준공검수내역확인 등 내부처리 업무 지원(전자결재/전자계약 등 연계 처리) - 용역마스터 변경 시, 변경 전·후 비교 기능 - 용역오더 실적 기반 집행률/잔액계산 등 비용 정보 확인 기능(계약액 대비) - 준공/기성 검사결과 및 검수자료(검사성적서, 사진 등) 관리 기능 - 본사 통합발주(소형 CHP 경상정비 용역 등) 용역 설계 및 지사별 사후관리 기능 지원 | K28: O | L28: X | M28: VIII. 유지보수
A29: SFR | B29: =A29&"-"&TEXT(COUNTIF($A$4:$A29, A29), "000") -> SFR-025 | D29: =IFERROR(VLOOKUP(C29,B:F,5,0),"") | E29: 작업관리 | F29: 공사오더 조회 및 생성 | G29: 필수 | H29: 공사오더 관리 | I29: ○ 공사오더 관리 - 공사마스터에 속하는 공사오더 관리 기능 - 공사오더 일반정보(설비마스터/설계자/보수/운영/정비부서/작업기간/작업등급/작업허가여부 등) 및 상세정보(공량/자재/경비/Red Tag 등) 관리 기능 - 상세정보에서 작업항목/작업항목별 공량/자재/경비/Red Tag 등의 설계 기능 및 각 설계내역의 총 금액 자동 산출 기능 - 기존 공사오더 설계 내역(공량/자재/경비설계 등) 전체·일부 복사 기능 - 설비별 적합 설계 이력 추천/적용 기능(AI 기술 활용 등 제안사 특화 기능 제시) - 품셈 및 물가정보 관리 기능(전산화 및 조회/선택) - 경비 설계시 항목별 산출근거 자료 관리 및 총경비 금액 중 도급분/사급분 금액 자동계산 기능 - 협력사별 견적 등록 기능(외부 접근) - 설비마스터에 기 등록된 Red Tag 정보 자동 연계 기능(수정 가능) - 설비마스터에 Red Tag 미등록 시, Red Tag 설계 이력 추천/적용 기능(AI 기술 활용 등 제안사 특화 기능 제시) - 필수 항목 누락, 수량/단가 입력 오류, 중복 품목 등록 등 사용자 입력 오류 검증 및 안내 기능 - 설비마스터 다중 선택 후, 공사오더 등록 및 일괄 승인 처리 기능 - 우리공사 표준시스템인 '스마트 안전관리 플랫폼'과 연계하여 안전작업허가서 관리 | K29: O | L29: X | M29: VIII. 유지보수
A30: SFR | B30: =A30&"-"&TEXT(COUNTIF($A$4:$A30, A30), "000") -> SFR-026 | D30: =IFERROR(VLOOKUP(C30,B:F,5,0),"") | E30: 작업관리 | F30: 공사 작업결과 입력 | G30: 필수 | H30: 공사오더 - 작업결과 관리 | I30: ○ 공사오더 - 작업결과 관리 - 실작업기간/작업형태/작업내용/작업결과/수행사진/관련자료첨부 등 관리 기능 - 작업결과는 승인 후 대상 설비의 정비 이력으로 자동 반영 - 정기점검 주기 관리 및 차기 정기점검보수 일정 자동 등록 기능 | K30: O | L30: O | M30: VIII. 유지보수
A31: SFR | B31: =A31&"-"&TEXT(COUNTIF($A$4:$A31, A31), "000") -> SFR-027 | D31: =IFERROR(VLOOKUP(C31,B:F,5,0),"") | E31: 작업관리 | F31: 설계기준 -설계기준서 관리 | G31: 필수 | H31: 공사오더 - 설계기준서 관리 | I31: ○ 공사오더 - 설계기준서 관리 - 설비·설비군·기능위치에 적용 가능한 작업등급(A/B/C 등급 등)별 설계기준서 작성 - 설계기준서에서 작업내용/작업절차/자재/공량/품셈 등의 정보를 관리 - 신규 생성 시, 과거 동일/유사 설계이력을 조회/추천/적용 기능(AI 기술 활용 등 제안사 특화 기능 제시) - 공사용/예방정비용/경상정비용 등의 종류 구분 기능 - 설계기준서의 버전관리 및 이전 버전과의 비교 기능 - 공사 열원보수표준품셈을 반영하여, 설비마스터 內 DB화된 설비 용량에 따라 설계기준서의 용량을 적용한 설계기준서 자동생성 기능 제공 | M31: VIII. 유지보수
A32: SFR | B32: =A32&"-"&TEXT(COUNTIF($A$4:$A32, A32), "000") -> SFR-028 | D32: =IFERROR(VLOOKUP(C32,B:F,5,0),"") | E32: 작업관리 | F32: 설계기준 -제비율표 관리 | G32: 필수 | H32: 공사오더 - 제비율표 관리 | I32: ○ 공사오더 - 제비율표 관리 - 제비율표는 조달청/물가정보 사이트에서 공개되는 정보를 전산화(전산화 방안 제시) - 항목/공사종류/공사기간/공사규모 등 다차원 분류 및 코드로 관리 - 해당 항목 선택 시, 설계에 반영 기능 - 제경비 기준시점별 이력 관리 및 기준 선택 시, 해당 항목 일괄적용 기능 - 비율, 소수점 자릿수, 반올림/버림 등의 규칙 설정 기능 - 'SAP ERP와 동일한 소수점 처리 라이브러리/로직'을 적용하여 정합성 보장 | M32: VIII. 유지보수
A33: SFR | B33: =A33&"-"&TEXT(COUNTIF($A$4:$A33, A33), "000") -> SFR-029 | D33: =IFERROR(VLOOKUP(C33,B:F,5,0),"") | E33: 작업관리 | F33: Red Tag 관리 | G33: 필수 | H33: Red Tag 관리 | I33: ○ Red Tag 관리 - Red Tag 조회/발행/취소/회수 관리 기능 - Red Tag 상태/발행일시/발행설비/조작요청내용 등의 정보 관리 기능 - 시스템 발행 및 수기 발행 등의 구분 기능 - 시스템 발행 시, Red Tag 설계된 오더 검색 및 Red Tag 설계 내용 조회·발행·출력 - 수기 발행 시, 작업오더/공사오더 없이 대상 설비별 관리(필요 시, 오더에 연결 가능) - 수기 발행 시, 대상 설비의 설비마스터 표준 Red Tag 자동 입력 및 수정 기능 - 다수 Red Tag에 대한 일괄 발행/취소/출력 지원 - Red Tag 발행 대상 설비에 미회수 Red Tag 존재 시 경고 - Red Tag 출력 시, 연계된 LOTO 번호 정보 자동 인쇄 기능 - Red Tag 바코드 스캔/입력에 의한 상세 내역 확인 및 회수처리 기능 - 회수 예정일 임박/지연, 장기 미회수, 중복 발행 시 담당 부서에 알림 제공 기능 - 모바일에서 발행/출력 요청, 스캔 회수, 사진 첨부 기능 지원 - 각 지사별 Red -Tag 발행 프린터와 연계하여 출력기능 지원 | K33: O | L33: O | M33: VIII. 유지보수
A34: SFR | B34: =A34&"-"&TEXT(COUNTIF($A$4:$A34, A34), "000") -> SFR-030 | D34: =IFERROR(VLOOKUP(C34,B:F,5,0),"") | E34: 작업관리 | F34: 예방정비관리 | G34: 필수 | H34: 예방정비 필요 설비 조회/신규 지정, 설비별 예방정비작업 사전 설계, 일정 등록 및 작업오더 자동 발행 | I34: ○ 예방정비 관리 - 예방정비 대상 설비 조회/신규 지정, 예방정비 작업오더 사전 설계, 일정 등록 및 작업오더 자동 발행 기능 - 대상 설비 신규 등록 시, 동일 설비의 예방정비 작업오더 사전 설계 내역 조회 및 적용 기능 제공(AI 기술 활용 등 제안사 특화 기능 제시) - 자동 오더 발행 설정(예방정비 주기·오더자동생성조건·시행기준일·작업등급) 관리 - 다수 설비 선택 후 동일 설계 내용 일괄 적용 기능 - 기 등록 예방정비 대상 설비의 과거 정비 이력 정보 제공 - 연도별 예방정비 시행 예정 설비리스트 자동 생성 - 생성된 연도의 설비별 예방정비 일정 삭제/변경 가능해야 함 - 예방정비 작업오더 자동 생성 후 담당부서/담당자 알림 기능 제공 - 예방정비 일정표는 캘린더와 리스트로 제공, 엑셀 등 파일로 내보내기 지원 - 예방정비 작업오더 종결 시, 작업실적 연계를 통한 정비이력 정보 제공 기능 - 연도별 예방정비를 통한 중장기 유지보수 계획 및 실적 관리 (CNR-002) - 과거 6개년 지사별 중장기 유지보수 계획을 DB화 하여 시스템 반영 | M34: VIII. 유지보수
A35: SFR | B35: =A35&"-"&TEXT(COUNTIF($A$4:$A35, A35), "000") -> SFR-031 | D35: =IFERROR(VLOOKUP(C35,B:F,5,0),"") | E35: 작업관리 | F35: 법정검사 | G35: 필수 | H35: 법정검사 대상 설비 조회/신규지정, 설비별 법정검사 일정 등록 및 실적 확인 | I35: ○ 법정검사 관리 - 법정검사 대상 설비 조회/지정, 설비별 법정검사 신규등록 및 상세내용/실적, 관련 법조항 확인 기능 제공 - 법정검사 항목별 시행/미시행 여부 선택 기능 제공 - 법정검사 신규 입력 시, 검사주기, 검사시기, 기준일자 등록으로 검사일정 자동 생성 기능 제공 - 법정검사 실적 조회 시, 검사 성적서, 검사결과보고서, 시정조치 확인서 등 첨부 자료 등록/조회/다운로드 - 연도별/월별 법정검사 계획 및 실적 건수 집계/조회 - 월별 검사 계획 리스트 조회 및 검사결과 입력 기능 제공 - 월별 검사 실적 리스트 및 검사결과 조회 기능 제공 - 예정일 임박, 실적 미입력, 법정 기한 만료 예정에 대한 알림 기능 제공 | M35: VIII. 유지보수
A36: SFR | B36: =A36&"-"&TEXT(COUNTIF($A$4:$A36, A36), "000") -> SFR-032 | D36: =IFERROR(VLOOKUP(C36,B:F,5,0),"") | E36: 작업관리 | F36: 예방점검관리 | G36: 필수 | H36: 예방점검 대상 설비 등록, 점검항목·점검기준·점검일정 설계 및 예방점검 결과 등 예방점검 전과정 관리 | I36: ○ 예방점검마스터 - 예방점검 계획 수립 및 예방점검 등록/이력 조회 관리 기능 - 예방점검 계획 수립 시, 예방점검 대상 설비 등록 및 점검 Check Sheet(점검항목, 점검기준)/점검주기 관리, 연간 일정 관리 가능 제공 - 예방점검 항목별 시행/미시행 여부 선택 기능 제공 - 예방점검 신규 입력 시, 일반정보(점검명, 점검주기, 담당부서 등) 및 대상 설비 리스트, 대상설비별 점검항목/점검 기준 등록·수정·저장 기능 제공 - 동일 점검을 여러 설비에 일괄 추가 및 삭제 기능 ○ 예방점검 - 예방점검 일정 생성/조회 및 예방점검 결과 입력, 과거 점검 이력 조회 관리 기능 - 예방점검 일정 생성 시, 연간 일정과 주간 계획 상호 연계 - 예방점검마스터에서 설정한 점검주기에 따른 점검항목별 주단위(1주~52주) 연간 예방점검 일정 자동 생성 - 예방점검마스터에서 설정한 점검 수행 요일 정보에 따른 주간 예방점검 일정 자동 생성 - 요일별 등록된 점검 일정 목록 복사/붙여넣기 기능 지원 - 주간 예방점검 일정표에서 점검 Check Sheet 조회/출력 및 일자별 점검결과 입력 바로가기 기능 제공 - 점검결과 입력 시, 점검기준치 이탈에 대한 경고 알림 제공 - 점검결과 입력 시, 점검 결과 불량 항목에 대한 작업지시서 생성 연계 기능 제공 - 점검 결과 양호 항목에 대한 일괄 승인 요청 기능 - 모바일에서 QR/바코드 스캔 기반 예방점검 일정 조회, 체크리스트 조회, 점검 결과 입력, 사진 첨부 기능 지원 - 점검 이력 조회 시, 설비별/점검항목별 상세 결과 및 추이 그래프 제공 - 일정 자동 생성 시 '공사 휴무일 및 대보수 기간 자동 회피' 로직과, 부서별 '주간 최대 점검 가능 건수(Capa)'를 설정하여 일정을 평탄화(Leveling)하는 알고리즘을 제안해야 함. - 예방점검 결과 입력 시, 'GPS 위치 및 QR 인증' 을 통해 실제 설비 근처에 있어야만 '완료' 버튼이 활성화되는 기능을 도입하여 허위 점검 원천 차단 | K36: O | L36: O | M36: VIII. 유지보수
A37: SFR | B37: =A37&"-"&TEXT(COUNTIF($A$4:$A37, A37), "000") -> SFR-033 | D37: =IFERROR(VLOOKUP(C37,B:F,5,0),"") | E37: 작업관리 | F37: 작업 통계 | G37: 필수 | H37: 경상정비, 공사, Red Tag, 예방점검 현황 및 운영상태 파악을 위한 작업 통계 제시 | I37: ○ 작업통계 관리 - 카테고리(작업, 공사, Red Tag, 예방점검)별 주요 지표 통계 조회·집계·분석 기능 - 기간, 지사, 사업장, 설비군, 설비, 담당부서 등의 조건에 대한 다중 필터 조회·집계 기능 - 주요 지표별 통계 데이터를 테이블 및 그래프로 제시 기능 제공 - 주요 지표에 대한 정의, 산식 정보 표시(툴팁, 안내문 등) 기능 - 주요 통계 지표별 전년동기/전월 대비 및 목표 대비 증감율 제공 - 통계 수치 단위 변환(원/천원/백만원, 시간/일 등) 지원 | M37: VIII. 유지보수
A38: SFR | B38: =A38&"-"&TEXT(COUNTIF($A$4:$A38, A38), "000") -> SFR-034 | D38: =IFERROR(VLOOKUP(C38,B:F,5,0),"") | E38: 고장관리 | F38: 고장속보 (상보) | G38: 필수 | H38: 고장속보(상보)의 등록/수정/조회 | I38: ○ 고장속보 관리 - 고장속보 조회 및 등록 기능 - 전 지사 고장속보 목록 확인 및 고장속보 상세 내역 확인 기능 - 모바일에서 고장속보 조회 및 신규 작성 지원 - TM 및 작업오더 발행 기능 제공 - 사진·관련문서 첨부, 미리보기 및 다운로드 지원 - 신규 등록 및 중요사항 변경(상태, 피해규모 등) 시 담당부서(담당자) 알람 제공 - 시간 입력 오류(발생시간 -작업개시시간 -종료시간) 등 자동 검증 기능 제공 (CNR-004) - 설비별 고장상보 대응 긴급작업 내역 표준화 및 DB화 용역 포함 ○ 고장상보 관리 - 고장상보 조회 및 등록 기능 - 전 지사 고장상보 목록 확인 및 고장상보 상세 내역 확인 기능 - 모바일에서 고장상보 조회 지원 - 고장속보 연계를 통한 데이터 자동 입력 기능 제공 - 고장상보 작성 시, 고장원인담당자 및 고장원인책임자 복수 지정 기능 - 신규 등록 및 중요사항 변경(상태, 피해규모 등) 시 담당부서(담당자) 알람 제공 - 시간 입력 오류(발생시간 -작업개시시간 -종료시간) 등 자동 검증 기능 제공 (CNR-004) - 설비별 고장상보 대응 긴급작업 내역 표준화 및 DB화 용역 포함 | K38: O | L38: O | M38: VIII. 유지보수
A39: SFR | B39: =A39&"-"&TEXT(COUNTIF($A$4:$A39, A39), "000") -> SFR-035 | D39: =IFERROR(VLOOKUP(C39,B:F,5,0),"") | E39: 계획 예방 정비관리 | F39: 계획 예방 정비 (결과) | G39: 필수 | H39: 계획 예방 정비 (결과) 보고 의 등록/수정/조회 | I39: ○ 계획 예방 정비(결과) 관리 - 계획 예방 정비(결과) 조회 및 등록 기능 - 전 지사 계획 예방 정비(결과) 목록 확인 및 계획 예방 정비(결과) 상세 내역 확인 기능 - 모바일에서 조회 및 신규 작성 지원 - TM 및 작업오더 발행시 매핑 기능 제공 - 사진·관련문서 첨부, 미리보기 및 다운로드 지원 - 신규 등록 및 중요사항 변경(상태, 피해규모 등) 시 담당부서(담당자) 알람 제공 - 시간 입력 오류(발생시간 -작업개시시간 -종료시간) 등 자동 검증 기능 제공 | K39: O | L39: X | M39: VIII. 유지보수
A40: SFR | B40: =A40&"-"&TEXT(COUNTIF($A$4:$A40, A40), "000") -> SFR-036 | D40: =IFERROR(VLOOKUP(C40,B:F,5,0),"") | E40: 고장관리 | F40: 고장 통계 | G40: 필수 | H40: 다양한 기준에 따른 고장통계의 조회·집계·분석 | I40: ○ 고장통계 관리 - 기간, 지사, 설비, 고장유형/고장모드, 고장원인, 중요도, 정비전략 등 조건에 따른 고장통계(표, 그래프 동시 제공)기능 - 지표에 대한 정의, 산식 정보 표시(툴팁, 안내문 등) 기능 - 주요 통계 지표별 전년동기/전월 대비 및 목표 대비 증감율 제공 - 모든 차트/표는 엑셀 등 문서로 다운로드 및 출력 기능 제공 | M40: VIII. 유지보수
...

Sheet 4. 산출물 목록
B1: 산출물 목록
B3: 구분 | C3: 업무구분 | D3: 활동구분 | E3: 산출물명 | F3: 요구사항 번호 | G3: 비고
B4: 1 | C4: 관리산출물 | D4: 착수 | E4: 착수계(착수신고서, 사업수행계획서, 품질보증계획서, 위험관리계획서) | F4: PMR-001
B5: 2 | E5: WBS | F5: PMR-001
B6: 3 | E6: 보안서약서 | F6: SER-005
B7: 4 | E7: 인터넷망 자체 보안성 검토 | F7: SER-012
B8: 5 | D8: 수행 | E8: 주간/월간 보고서, 중간·최종 보고서 등 회의록 | F8: PMR-004
B9: 6 | E9: 보안교육 결과보고서 | F9: SER-005
B10: 7 | E10: 자료관리대장 | F10: SER-005
B11: 8 | E11: 반출입관리대장 | F11: SER-005
B12: 9 | D12: 완료 | E12: 완료 보고서 | F12: PMR-004
B13: 10 | E13: 자원현황 보고서 | F13: PSR-001
B14: 11 | E14: 보안확약서 | F14: SER-007
B15: 12 | D15: 매뉴얼 | E15: 사용자 매뉴얼 | F15: SFR-071
B16: 13 | E16: 관리자 매뉴얼 | F16: SFR-071
B17: 14 | D17: 감리 | E17: 감리보고서 | F17: 감리용역 산출물
B18: 15 | E18: 감리결과 조치내역 확인 보고서 | F18: 감리용역 산출물
B19: 16 | D19: 종료 | E19: 준공검사확인서(준공조서, 기성부문산출내역, 검사확인서, 비용산출 최종내역) | F19: PMR-005
B20: 17 | E20: 정보시스템 현황보고서 | F20: PMR-005
B21: 18 | E21: 최종 프로그램 소스코드 및 디자인 원본 파일 일체 | F21: PMR-005
B22: 19 | E22: 정보화사업 현황보고서 | F22: COR-005
B23: 20 | E23: 단위테스트 계획/결과서 (기능별, 요구사항별, 등) | F23: TER-001, TER-002
B24: 21 | E24: 통합테스트 계획/결과서 | F24: TER-001, TER-002
B25: 22 | C25: 개발산출물 | D25: 분석 및 수행 | E25: 아키텍쳐 설계서 | F25: ECR-001
B26: 23 | E26: 메뉴구성 및 권한정의서 | F26: SFR-001
B27: 24 | E27: 프로그램 목록 | F27: PMR-008
B28: 25 | E28: 요구사항 정의서, 요구사항 추적표 | F28: PMR-009
B29: 26 | E29: 프로세스 정의서 | F29: CNR-001
B30: 27 | E30: 인터페이스 정의서 | F30: INR-001
B31: 28 | E31: 메뉴 목록 및 응용기능 차트 | F31: SFR-004
B32: 29 | E32: 메뉴 구성도 | F32: SFR-004
B33: 30 | E33: 화면설계서 | F33: SFR-004
B34: 31 | E34: 취약점 진단 수행 결과서 | F34: SER-009
B35: 32 | E35: 시큐어 코딩 점검 결과서 | F35: SER-009
B36: 33 | E36: DB암호화 점검 결과서 | F36: SER-010
B37: 34 | D37: 완료 | E37: 기술이전 계획서 | F37: PSR-004
B38: 35 | E38: 시스템 운영 및 유지관리 지침서 | F38: PSR-004
B39: 36 | D39: 데이터 품질 | E39: 데이터 품질진단계획서 | F39: QUR-001
B40: 37 | C40: 예방적 품질관리 (데이터 품질관리 지침 제8조의2) | D40: 계획 | E40: 예방적 품질관리 체크리스트 | F40: 사업 발주전 기제출
B41: 38 | D41: 설계 | E41: 표준용어 정의서(SMETA) | F41: DAR-001
...
